<?xml version="1.0" ?>
<!-- =================================================================================== -->
<!-- |    This document was autogenerated by xacro from naorobot.xacro                 | -->
<!-- |    EDITING THIS FILE BY HAND IS NOT RECOMMENDED                                 | -->
<!-- =================================================================================== -->
<!-- ***************************************************************** 
 ****** File automatically generated by generate_urdf.py script ****** 
 ********************************************************************* -->
<robot name="naoH25V40" xmlns:xacro="http://www.ros.org/wiki/xacro">
  <transmission name="HeadYaw_Transmission">
    <type>transmission_interface/SimpleTransmission</type>
    <joint name="HeadYaw">
      <hardwareInterface>PositionJointInterface</hardwareInterface>
    </joint>
    <actuator name="HeadYaw_Motor">
      <!-- Dummy Values -->
      <hardwareInterface>PositionJointInterface</hardwareInterface>
      <mechanicalReduction>150.27</mechanicalReduction>
    </actuator>
  </transmission>
  <transmission name="HeadPitch_Transmission">
    <type>transmission_interface/SimpleTransmission</type>
    <joint name="HeadPitch">
      <hardwareInterface>PositionJointInterface</hardwareInterface>
    </joint>
    <actuator name="HeadPitch_Motor">
      <!-- Dummy Values -->
      <hardwareInterface>PositionJointInterface</hardwareInterface>
      <mechanicalReduction>173.22</mechanicalReduction>
    </actuator>
  </transmission>
  <transmission name="LShoulderPitch_Transmission">
    <type>transmission_interface/SimpleTransmission</type>
    <joint name="LShoulderPitch">
      <hardwareInterface>PositionJointInterface</hardwareInterface>
    </joint>
    <actuator name="LShoulderPitch_Motor">
      <hardwareInterface>PositionJointInterface</hardwareInterface>
      <mechanicalReduction>150.27</mechanicalReduction>
    </actuator>
  </transmission>
  <transmission name="LShoulderRoll_Transmission">
    <type>transmission_interface/SimpleTransmission</type>
    <joint name="LShoulderRoll">
      <hardwareInterface>PositionJointInterface</hardwareInterface>
    </joint>
    <actuator name="LShoulderRoll_Motor">
      <hardwareInterface>PositionJointInterface</hardwareInterface>
      <mechanicalReduction>173.22</mechanicalReduction>
    </actuator>
  </transmission>
  <transmission name="LElbowYaw_Transmission">
    <type>transmission_interface/SimpleTransmission</type>
    <joint name="LElbowYaw">
      <hardwareInterface>PositionJointInterface</hardwareInterface>
    </joint>
    <actuator name="LElbowYaw_Motor">
      <hardwareInterface>PositionJointInterface</hardwareInterface>
      <mechanicalReduction>150.27</mechanicalReduction>
    </actuator>
  </transmission>
  <transmission name="LElbowRoll_Transmission">
    <type>transmission_interface/SimpleTransmission</type>
    <joint name="LElbowRoll">
      <hardwareInterface>PositionJointInterface</hardwareInterface>
    </joint>
    <actuator name="LElbowRoll_Motor">
      <hardwareInterface>PositionJointInterface</hardwareInterface>
      <mechanicalReduction>173.22</mechanicalReduction>
    </actuator>
  </transmission>
  <transmission name="LWristYaw_Transmission">
    <type>transmission_interface/SimpleTransmission</type>
    <joint name="LWristYaw">
      <hardwareInterface>PositionJointInterface</hardwareInterface>
    </joint>
    <actuator name="LWristYaw_Motor">
      <hardwareInterface>PositionJointInterface</hardwareInterface>
      <mechanicalReduction>50.61</mechanicalReduction>
    </actuator>
  </transmission>
  <transmission name="LHand_Transmission">
    <type>transmission_interface/SimpleTransmission</type>
    <joint name="LHand">
      <hardwareInterface>PositionJointInterface</hardwareInterface>
    </joint>
    <actuator name="LHand_Motor">
      <hardwareInterface>PositionJointInterface</hardwareInterface>
      <mechanicalReduction>36.24</mechanicalReduction>
    </actuator>
  </transmission>
  <transmission name="RShoulderPitch_Transmission">
    <type>transmission_interface/SimpleTransmission</type>
    <joint name="RShoulderPitch">
      <hardwareInterface>PositionJointInterface</hardwareInterface>
    </joint>
    <actuator name="RShoulderPitch_Motor">
      <hardwareInterface>PositionJointInterface</hardwareInterface>
      <mechanicalReduction>150.27</mechanicalReduction>
    </actuator>
  </transmission>
  <transmission name="RShoulderRoll_Transmission">
    <type>transmission_interface/SimpleTransmission</type>
    <joint name="RShoulderRoll">
      <hardwareInterface>PositionJointInterface</hardwareInterface>
    </joint>
    <actuator name="RShoulderRoll_Motor">
      <hardwareInterface>PositionJointInterface</hardwareInterface>
      <mechanicalReduction>173.22</mechanicalReduction>
    </actuator>
  </transmission>
  <transmission name="RElbowYaw_Transmission">
    <type>transmission_interface/SimpleTransmission</type>
    <joint name="RElbowYaw">
      <hardwareInterface>PositionJointInterface</hardwareInterface>
    </joint>
    <actuator name="RElbowYaw_Motor">
      <hardwareInterface>PositionJointInterface</hardwareInterface>
      <mechanicalReduction>150.27</mechanicalReduction>
    </actuator>
  </transmission>
  <transmission name="RElbowRoll_Transmission">
    <type>transmission_interface/SimpleTransmission</type>
    <joint name="RElbowRoll">
      <hardwareInterface>PositionJointInterface</hardwareInterface>
    </joint>
    <actuator name="RElbowRoll_Motor">
      <hardwareInterface>PositionJointInterface</hardwareInterface>
      <mechanicalReduction>173.22</mechanicalReduction>
    </actuator>
  </transmission>
  <transmission name="RWristYaw_Transmission">
    <type>transmission_interface/SimpleTransmission</type>
    <joint name="RWristYaw">
      <hardwareInterface>PositionJointInterface</hardwareInterface>
    </joint>
    <actuator name="RWristYaw_Motor">
      <hardwareInterface>PositionJointInterface</hardwareInterface>
      <mechanicalReduction>50.61</mechanicalReduction>
    </actuator>
  </transmission>
  <transmission name="RHand_Transmission">
    <type>transmission_interface/SimpleTransmission</type>
    <joint name="RHand">
      <hardwareInterface>PositionJointInterface</hardwareInterface>
    </joint>
    <actuator name="RHand_Motor">
      <hardwareInterface>PositionJointInterface</hardwareInterface>
      <mechanicalReduction>36.24</mechanicalReduction>
    </actuator>
  </transmission>
  <transmission name="LHipYawPitch_Transmission">
    <type>transmission_interface/SimpleTransmission</type>
    <joint name="LHipYawPitch">
      <hardwareInterface>PositionJointInterface</hardwareInterface>
    </joint>
    <actuator name="LHipYawPitch_Motor">
      <!-- Dummy Values -->
      <hardwareInterface>PositionJointInterface</hardwareInterface>
      <mechanicalReduction>201.3</mechanicalReduction>
    </actuator>
  </transmission>
  <transmission name="LHipRoll_Transmission">
    <type>transmission_interface/SimpleTransmission</type>
    <joint name="LHipRoll">
      <hardwareInterface>PositionJointInterface</hardwareInterface>
    </joint>
    <actuator name="LHipRoll_Motor">
      <!-- Dummy Values -->
      <hardwareInterface>PositionJointInterface</hardwareInterface>
      <mechanicalReduction>201.3</mechanicalReduction>
    </actuator>
  </transmission>
  <transmission name="LHipPitch_Transmission">
    <type>transmission_interface/SimpleTransmission</type>
    <joint name="LHipPitch">
      <hardwareInterface>PositionJointInterface</hardwareInterface>
    </joint>
    <actuator name="LHipPitch_Motor">
      <!-- Dummy Values -->
      <hardwareInterface>PositionJointInterface</hardwareInterface>
      <mechanicalReduction>130.85</mechanicalReduction>
    </actuator>
  </transmission>
  <transmission name="LKneePitch_Transmission">
    <type>transmission_interface/SimpleTransmission</type>
    <joint name="LKneePitch">
      <hardwareInterface>PositionJointInterface</hardwareInterface>
    </joint>
    <actuator name="LKneePitch_Motor">
      <!-- Dummy Values -->
      <hardwareInterface>PositionJointInterface</hardwareInterface>
      <mechanicalReduction>130.85</mechanicalReduction>
    </actuator>
  </transmission>
  <transmission name="LAnklePitch_Transmission">
    <type>transmission_interface/SimpleTransmission</type>
    <joint name="LAnklePitch">
      <hardwareInterface>PositionJointInterface</hardwareInterface>
    </joint>
    <actuator name="LAnklePitch_Motor">
      <!-- Dummy Values -->
      <hardwareInterface>PositionJointInterface</hardwareInterface>
      <mechanicalReduction>130.85</mechanicalReduction>
    </actuator>
  </transmission>
  <transmission name="LAnkleRoll_Transmission">
    <type>transmission_interface/SimpleTransmission</type>
    <joint name="LAnkleRoll">
      <hardwareInterface>PositionJointInterface</hardwareInterface>
    </joint>
    <actuator name="LAnkleRoll_Motor">
      <!-- Dummy Values -->
      <hardwareInterface>PositionJointInterface</hardwareInterface>
      <mechanicalReduction>201.3</mechanicalReduction>
    </actuator>
  </transmission>
  <transmission name="RHipYawPitch_Transmission">
    <type>transmission_interface/SimpleTransmission</type>
    <joint name="RHipYawPitch">
      <hardwareInterface>PositionJointInterface</hardwareInterface>
    </joint>
    <actuator name="RHipYawPitch_Motor">
      <!-- Dummy Values -->
      <hardwareInterface>PositionJointInterface</hardwareInterface>
      <mechanicalReduction>201.3</mechanicalReduction>
    </actuator>
  </transmission>
  <transmission name="RHipRoll_Transmission">
    <type>transmission_interface/SimpleTransmission</type>
    <joint name="RHipRoll">
      <hardwareInterface>PositionJointInterface</hardwareInterface>
    </joint>
    <actuator name="RHipRoll_Motor">
      <!-- Dummy Values -->
      <hardwareInterface>PositionJointInterface</hardwareInterface>
      <mechanicalReduction>201.3</mechanicalReduction>
    </actuator>
  </transmission>
  <transmission name="RHipPitch_Transmission">
    <type>transmission_interface/SimpleTransmission</type>
    <joint name="RHipPitch">
      <hardwareInterface>PositionJointInterface</hardwareInterface>
    </joint>
    <actuator name="RHipPitch_Motor">
      <!-- Dummy Values -->
      <hardwareInterface>PositionJointInterface</hardwareInterface>
      <mechanicalReduction>130.85</mechanicalReduction>
    </actuator>
  </transmission>
  <transmission name="RKneePitch_Transmission">
    <type>transmission_interface/SimpleTransmission</type>
    <joint name="RKneePitch">
      <hardwareInterface>PositionJointInterface</hardwareInterface>
    </joint>
    <actuator name="RKneePitch_Motor">
      <!-- Dummy Values -->
      <hardwareInterface>PositionJointInterface</hardwareInterface>
      <mechanicalReduction>130.85</mechanicalReduction>
    </actuator>
  </transmission>
  <transmission name="RAnklePitch_Transmission">
    <type>transmission_interface/SimpleTransmission</type>
    <joint name="RAnklePitch">
      <hardwareInterface>PositionJointInterface</hardwareInterface>
    </joint>
    <actuator name="RAnklePitch_Motor">
      <!-- Dummy Values -->
      <hardwareInterface>PositionJointInterface</hardwareInterface>
      <mechanicalReduction>130.85</mechanicalReduction>
    </actuator>
  </transmission>
  <transmission name="RAnkleRoll_Transmission">
    <type>transmission_interface/SimpleTransmission</type>
    <joint name="RAnkleRoll">
      <hardwareInterface>PositionJointInterface</hardwareInterface>
    </joint>
    <actuator name="RAnkleRoll_Motor">
      <!-- Dummy Values -->
      <hardwareInterface>PositionJointInterface</hardwareInterface>
      <mechanicalReduction>201.3</mechanicalReduction>
    </actuator>
  </transmission>
  <gazebo>
    <plugin filename="libgazebo_ros_control.so" name="gazebo_ros_control">
      <robotNamespace>/nao_dcm</robotNamespace>
      <robotSimType>gazebo_ros_control/DefaultRobotHWSim</robotSimType>
    </plugin>
    <plugin filename="libgazebo_ros_imu.so" name="gazebo_ros_imu_controller">
      <robotNamespace>/nao_dcm</robotNamespace>
      <topicName>imu_data</topicName>
      <bodyName>imu</bodyName>
      <frameId>imu</frameId>
      <gaussianNoise>2.89e-08</gaussianNoise>
      <accelGaussianNoise>2.89e-08 2.89e-08 2.89e-08</accelGaussianNoise>
      <rateGaussianNoise>2.89e-08 2.89e-08 2.89e-08</rateGaussianNoise>
      <headingGaussianNoise>2.89e-08 2.89e-08 2.89e-08</headingGaussianNoise>
      <xyzOffsets>0 0 0</xyzOffsets>
      <rpyOffsets>0 0 0</rpyOffsets>
      <updateRate>30.0</updateRate>
      <alwaysOn>true</alwaysOn>
    </plugin>
    <!--        <plugin name="gazebo_ros_imu_controller" filename="${imu_plugin}">
            <robotNamespace>/nao_dcm</robotNamespace>
            <topicName>imu_data</topicName>
            <bodyName>imu</bodyName>
            <frameId>imu</frameId>
            <gaussianNoise>2.89e-08</gaussianNoise>
            <accelGaussianNoise>2.89e-08 2.89e-08 2.89e-08</accelGaussianNoise>
            <rateGaussianNoise>2.89e-08 2.89e-08 2.89e-08</rateGaussianNoise>
            <headingGaussianNoise>2.89e-08 2.89e-08 2.89e-08</headingGaussianNoise>
            <xyzOffsets>0 0 0</xyzOffsets>
            <rpyOffsets>0 0 0</rpyOffsets>
            <updateRate>30.0</updateRate>
            <alwaysOn>true</alwaysOn>
        </plugin>
-->
    <!-- Mimic joints through plugin develop by costashatz based on implementation by Goncalo Cabrita -->
    <plugin filename="libroboticsgroup_gazebo_mimic_joint_plugin.so" name="mimic_hipyawpitch">
      <joint>LHipYawPitch</joint>
      <mimicJoint>RHipYawPitch</mimicJoint>
      <multiplier>1.0</multiplier>
      <offset>0.0</offset>
    </plugin>
    <plugin filename="libroboticsgroup_gazebo_mimic_joint_plugin.so" name="mimic_LFinger1">
      <joint>LHand</joint>
      <mimicJoint>LFinger1</mimicJoint>
      <multiplier>-0.785398163398</multiplier>
      <offset>0.785398163398</offset>
    </plugin>
    <plugin filename="libroboticsgroup_gazebo_mimic_joint_plugin.so" name="mimic_LFinger1_1">
      <joint>LHand</joint>
      <mimicJoint>LFinger1_1</mimicJoint>
      <multiplier>-0.785398163398</multiplier>
      <offset>0.785398163398</offset>
    </plugin>
    <plugin filename="libroboticsgroup_gazebo_mimic_joint_plugin.so" name="mimic_LFinger1_2">
      <joint>LHand</joint>
      <mimicJoint>LFinger1_2</mimicJoint>
      <multiplier>-0.785398163398</multiplier>
      <offset>0.785398163398</offset>
    </plugin>
    <plugin filename="libroboticsgroup_gazebo_mimic_joint_plugin.so" name="mimic_LFinger2">
      <joint>LHand</joint>
      <mimicJoint>LFinger2</mimicJoint>
      <multiplier>-0.785398163398</multiplier>
      <offset>0.785398163398</offset>
    </plugin>
    <plugin filename="libroboticsgroup_gazebo_mimic_joint_plugin.so" name="mimic_LFinger2_1">
      <joint>LHand</joint>
      <mimicJoint>LFinger2_1</mimicJoint>
      <multiplier>-0.785398163398</multiplier>
      <offset>0.785398163398</offset>
    </plugin>
    <plugin filename="libroboticsgroup_gazebo_mimic_joint_plugin.so" name="mimic_LFinger2_2">
      <joint>LHand</joint>
      <mimicJoint>LFinger2_2</mimicJoint>
      <multiplier>-0.785398163398</multiplier>
      <offset>0.785398163398</offset>
    </plugin>
    <plugin filename="libroboticsgroup_gazebo_mimic_joint_plugin.so" name="mimic_RFinger1">
      <joint>RHand</joint>
      <mimicJoint>RFinger1</mimicJoint>
      <multiplier>-0.785398163398</multiplier>
      <offset>0.785398163398</offset>
    </plugin>
    <plugin filename="libroboticsgroup_gazebo_mimic_joint_plugin.so" name="mimic_RFinger1_1">
      <joint>RHand</joint>
      <mimicJoint>RFinger1_1</mimicJoint>
      <multiplier>-0.785398163398</multiplier>
      <offset>0.785398163398</offset>
    </plugin>
    <plugin filename="libroboticsgroup_gazebo_mimic_joint_plugin.so" name="mimic_RFinger1_2">
      <joint>RHand</joint>
      <mimicJoint>RFinger1_2</mimicJoint>
      <multiplier>-0.785398163398</multiplier>
      <offset>0.785398163398</offset>
    </plugin>
    <plugin filename="libroboticsgroup_gazebo_mimic_joint_plugin.so" name="mimic_RFinger2">
      <joint>RHand</joint>
      <mimicJoint>RFinger2</mimicJoint>
      <multiplier>-0.785398163398</multiplier>
      <offset>0.785398163398</offset>
    </plugin>
    <plugin filename="libroboticsgroup_gazebo_mimic_joint_plugin.so" name="mimic_RFinger2_1">
      <joint>RHand</joint>
      <mimicJoint>RFinger2_1</mimicJoint>
      <multiplier>-0.785398163398</multiplier>
      <offset>0.785398163398</offset>
    </plugin>
    <plugin filename="libroboticsgroup_gazebo_mimic_joint_plugin.so" name="mimic_RFinger2_2">
      <joint>RHand</joint>
      <mimicJoint>RFinger2_2</mimicJoint>
      <multiplier>-0.785398163398</multiplier>
      <offset>0.785398163398</offset>
    </plugin>
    <plugin filename="libroboticsgroup_gazebo_mimic_joint_plugin.so" name="LThumb1_joint">
      <joint>LHand</joint>
      <mimicJoint>LThumb1_joint</mimicJoint>
      <multiplier>-0.785398163398</multiplier>
      <offset>0.785398163398</offset>
    </plugin>
    <plugin filename="libroboticsgroup_gazebo_mimic_joint_plugin.so" name="LThumb1_2">
      <joint>LHand</joint>
      <mimicJoint>LThumb1_2</mimicJoint>
      <multiplier>-0.785398163398</multiplier>
      <offset>0.785398163398</offset>
    </plugin>
    <plugin filename="libroboticsgroup_gazebo_mimic_joint_plugin.so" name="RThumb1_joint">
      <joint>RHand</joint>
      <mimicJoint>RThumb1_joint</mimicJoint>
      <multiplier>-0.785398163398</multiplier>
      <offset>0.785398163398</offset>
    </plugin>
    <plugin filename="libroboticsgroup_gazebo_mimic_joint_plugin.so" name="RThumb1_2">
      <joint>RHand</joint>
      <mimicJoint>RThumb1_2</mimicJoint>
      <multiplier>-0.785398163398</multiplier>
      <offset>0.785398163398</offset>
    </plugin>
    <plugin filename="libroboticsgroup_gazebo_disable_link_plugin.so" name="LFinger11">
      <link>LFinger11</link>
    </plugin>
    <plugin filename="libroboticsgroup_gazebo_disable_link_plugin.so" name="LFinger12">
      <link>LFinger12</link>
    </plugin>
    <plugin filename="libroboticsgroup_gazebo_disable_link_plugin.so" name="LFinger13">
      <link>LFinger13</link>
    </plugin>
    <plugin filename="libroboticsgroup_gazebo_disable_link_plugin.so" name="LFinger21">
      <link>LFinger21</link>
    </plugin>
    <plugin filename="libroboticsgroup_gazebo_disable_link_plugin.so" name="LFinger22">
      <link>LFinger22</link>
    </plugin>
    <plugin filename="libroboticsgroup_gazebo_disable_link_plugin.so" name="LFinger23">
      <link>LFinger23</link>
    </plugin>
    <plugin filename="libroboticsgroup_gazebo_disable_link_plugin.so" name="LThumb1">
      <link>LThumb1</link>
    </plugin>
    <plugin filename="libroboticsgroup_gazebo_disable_link_plugin.so" name="LThumb2">
      <link>LThumb2</link>
    </plugin>
    <plugin filename="libroboticsgroup_gazebo_disable_link_plugin.so" name="l_gripper">
      <link>l_gripper</link>
    </plugin>
    <plugin filename="libroboticsgroup_gazebo_disable_link_plugin.so" name="RFinger11">
      <link>RFinger11</link>
    </plugin>
    <plugin filename="libroboticsgroup_gazebo_disable_link_plugin.so" name="RFinger12">
      <link>RFinger12</link>
    </plugin>
    <plugin filename="libroboticsgroup_gazebo_disable_link_plugin.so" name="RFinger13">
      <link>RFinger13</link>
    </plugin>
    <plugin filename="libroboticsgroup_gazebo_disable_link_plugin.so" name="RFinger21">
      <link>RFinger21</link>
    </plugin>
    <plugin filename="libroboticsgroup_gazebo_disable_link_plugin.so" name="RFinger22">
      <link>RFinger22</link>
    </plugin>
    <plugin filename="libroboticsgroup_gazebo_disable_link_plugin.so" name="RFinger23">
      <link>RFinger23</link>
    </plugin>
    <plugin filename="libroboticsgroup_gazebo_disable_link_plugin.so" name="RThumb1">
      <link>RThumb1</link>
    </plugin>
    <plugin filename="libroboticsgroup_gazebo_disable_link_plugin.so" name="RThumb2">
      <link>RThumb2</link>
    </plugin>
    <plugin filename="libroboticsgroup_gazebo_disable_link_plugin.so" name="r_gripper">
      <link>r_gripper</link>
    </plugin>
  </gazebo>
  <gazebo reference="torso">
    <mu1>0.5</mu1>
    <mu2>0.5</mu2>
    <selfCollide>false</selfCollide>
    <turnGravityOff>false</turnGravityOff>
  </gazebo>
  <gazebo reference="Neck">
    <mu1>0.5</mu1>
    <mu2>0.5</mu2>
    <selfCollide>false</selfCollide>
    <turnGravityOff>false</turnGravityOff>
  </gazebo>
  <gazebo reference="Head">
    <mu1>0.5</mu1>
    <mu2>0.5</mu2>
    <selfCollide>false</selfCollide>
    <turnGravityOff>false</turnGravityOff>
  </gazebo>
  <gazebo reference="gaze">
    <mu1>0.5</mu1>
    <mu2>0.5</mu2>
    <selfCollide>false</selfCollide>
    <turnGravityOff>false</turnGravityOff>
  </gazebo>
  <gazebo reference="LShoulder">
    <mu1>0.5</mu1>
    <mu2>0.5</mu2>
    <selfCollide>false</selfCollide>
    <turnGravityOff>false</turnGravityOff>
  </gazebo>
  <gazebo reference="LBicep">
    <mu1>0.5</mu1>
    <mu2>0.5</mu2>
    <selfCollide>false</selfCollide>
    <turnGravityOff>false</turnGravityOff>
  </gazebo>
  <gazebo reference="LElbow">
    <mu1>0.5</mu1>
    <mu2>0.5</mu2>
    <selfCollide>false</selfCollide>
    <turnGravityOff>false</turnGravityOff>
  </gazebo>
  <gazebo reference="LForeArm">
    <mu1>0.5</mu1>
    <mu2>0.5</mu2>
    <selfCollide>false</selfCollide>
    <turnGravityOff>false</turnGravityOff>
  </gazebo>
  <gazebo reference="l_wrist">
    <mu1>0.5</mu1>
    <mu2>0.5</mu2>
    <selfCollide>false</selfCollide>
    <turnGravityOff>false</turnGravityOff>
  </gazebo>
  <gazebo reference="l_gripper">
    <mu1>0.5</mu1>
    <mu2>0.5</mu2>
    <selfCollide>false</selfCollide>
    <turnGravityOff>true</turnGravityOff>
  </gazebo>
  <gazebo reference="RShoulder">
    <mu1>0.5</mu1>
    <mu2>0.5</mu2>
    <selfCollide>false</selfCollide>
    <turnGravityOff>false</turnGravityOff>
  </gazebo>
  <gazebo reference="RBicep">
    <mu1>0.5</mu1>
    <mu2>0.5</mu2>
    <selfCollide>false</selfCollide>
    <turnGravityOff>false</turnGravityOff>
  </gazebo>
  <gazebo reference="RElbow">
    <mu1>0.5</mu1>
    <mu2>0.5</mu2>
    <selfCollide>false</selfCollide>
    <turnGravityOff>false</turnGravityOff>
  </gazebo>
  <gazebo reference="RForeArm">
    <mu1>0.5</mu1>
    <mu2>0.5</mu2>
    <selfCollide>false</selfCollide>
    <turnGravityOff>false</turnGravityOff>
  </gazebo>
  <gazebo reference="r_wrist">
    <mu1>0.5</mu1>
    <mu2>0.5</mu2>
    <selfCollide>false</selfCollide>
    <turnGravityOff>false</turnGravityOff>
  </gazebo>
  <gazebo reference="r_gripper">
    <mu1>0.5</mu1>
    <mu2>0.5</mu2>
    <selfCollide>false</selfCollide>
    <turnGravityOff>true</turnGravityOff>
  </gazebo>
  <gazebo reference="LFinger11">
    <mu1>0.5</mu1>
    <mu2>0.5</mu2>
    <selfCollide>false</selfCollide>
    <turnGravityOff>true</turnGravityOff>
  </gazebo>
  <gazebo reference="LFinger12">
    <mu1>0.5</mu1>
    <mu2>0.5</mu2>
    <selfCollide>false</selfCollide>
    <turnGravityOff>true</turnGravityOff>
  </gazebo>
  <gazebo reference="LFinger13">
    <mu1>0.5</mu1>
    <mu2>0.5</mu2>
    <selfCollide>false</selfCollide>
    <turnGravityOff>true</turnGravityOff>
  </gazebo>
  <gazebo reference="LFinger21">
    <mu1>0.5</mu1>
    <mu2>0.5</mu2>
    <selfCollide>false</selfCollide>
    <turnGravityOff>true</turnGravityOff>
  </gazebo>
  <gazebo reference="LFinger22">
    <mu1>0.5</mu1>
    <mu2>0.5</mu2>
    <selfCollide>false</selfCollide>
    <turnGravityOff>true</turnGravityOff>
  </gazebo>
  <gazebo reference="LFinger23">
    <mu1>0.5</mu1>
    <mu2>0.5</mu2>
    <selfCollide>false</selfCollide>
    <turnGravityOff>true</turnGravityOff>
  </gazebo>
  <gazebo reference="LThumb1">
    <mu1>0.5</mu1>
    <mu2>0.5</mu2>
    <selfCollide>false</selfCollide>
    <turnGravityOff>true</turnGravityOff>
  </gazebo>
  <gazebo reference="LThumb2">
    <mu1>0.5</mu1>
    <mu2>0.5</mu2>
    <selfCollide>false</selfCollide>
    <turnGravityOff>true</turnGravityOff>
  </gazebo>
  <gazebo reference="LPelvis">
    <mu1>0.5</mu1>
    <mu2>0.5</mu2>
    <selfCollide>false</selfCollide>
    <turnGravityOff>false</turnGravityOff>
  </gazebo>
  <gazebo reference="LHip">
    <mu1>0.5</mu1>
    <mu2>0.5</mu2>
    <selfCollide>false</selfCollide>
    <turnGravityOff>false</turnGravityOff>
  </gazebo>
  <gazebo reference="LThigh">
    <mu1>0.5</mu1>
    <mu2>0.5</mu2>
    <selfCollide>false</selfCollide>
    <turnGravityOff>false</turnGravityOff>
  </gazebo>
  <gazebo reference="LTibia">
    <mu1>0.5</mu1>
    <mu2>0.5</mu2>
    <selfCollide>false</selfCollide>
    <turnGravityOff>false</turnGravityOff>
  </gazebo>
  <gazebo reference="l_ankle">
    <mu1>0.5</mu1>
    <mu2>0.5</mu2>
    <selfCollide>false</selfCollide>
    <turnGravityOff>false</turnGravityOff>
  </gazebo>
  <gazebo reference="l_sole">
    <mu1>0.5</mu1>
    <mu2>0.5</mu2>
    <selfCollide>false</selfCollide>
    <turnGravityOff>false</turnGravityOff>
    <fdir1>1 0 0</fdir1>
    <maxVel>0.1</maxVel>
    <minDepth>0.003</minDepth>
  </gazebo>
  <gazebo reference="RPelvis">
    <mu1>0.5</mu1>
    <mu2>0.5</mu2>
    <selfCollide>false</selfCollide>
    <turnGravityOff>false</turnGravityOff>
  </gazebo>
  <gazebo reference="RHip">
    <mu1>0.5</mu1>
    <mu2>0.5</mu2>
    <selfCollide>false</selfCollide>
    <turnGravityOff>false</turnGravityOff>
  </gazebo>
  <gazebo reference="RThigh">
    <mu1>0.5</mu1>
    <mu2>0.5</mu2>
    <selfCollide>false</selfCollide>
    <turnGravityOff>false</turnGravityOff>
  </gazebo>
  <gazebo reference="RTibia">
    <mu1>0.5</mu1>
    <mu2>0.5</mu2>
    <selfCollide>false</selfCollide>
    <turnGravityOff>false</turnGravityOff>
  </gazebo>
  <gazebo reference="r_ankle">
    <mu1>0.5</mu1>
    <mu2>0.5</mu2>
    <selfCollide>false</selfCollide>
    <turnGravityOff>false</turnGravityOff>
  </gazebo>
  <gazebo reference="r_sole">
    <mu1>0.5</mu1>
    <mu2>0.5</mu2>
    <selfCollide>false</selfCollide>
    <turnGravityOff>false</turnGravityOff>
    <fdir1>1 0 0</fdir1>
    <maxVel>0.1</maxVel>
    <minDepth>0.003</minDepth>
  </gazebo>
  <gazebo reference="RFinger11">
    <mu1>0.5</mu1>
    <mu2>0.5</mu2>
    <selfCollide>false</selfCollide>
    <turnGravityOff>true</turnGravityOff>
  </gazebo>
  <gazebo reference="RFinger12">
    <mu1>0.5</mu1>
    <mu2>0.5</mu2>
    <selfCollide>false</selfCollide>
    <turnGravityOff>true</turnGravityOff>
  </gazebo>
  <gazebo reference="RFinger13">
    <mu1>0.5</mu1>
    <mu2>0.5</mu2>
    <selfCollide>false</selfCollide>
    <turnGravityOff>true</turnGravityOff>
  </gazebo>
  <gazebo reference="RFinger21">
    <mu1>0.5</mu1>
    <mu2>0.5</mu2>
    <selfCollide>false</selfCollide>
    <turnGravityOff>true</turnGravityOff>
  </gazebo>
  <gazebo reference="RFinger22">
    <mu1>0.5</mu1>
    <mu2>0.5</mu2>
    <selfCollide>false</selfCollide>
    <turnGravityOff>true</turnGravityOff>
  </gazebo>
  <gazebo reference="RFinger23">
    <mu1>0.5</mu1>
    <mu2>0.5</mu2>
    <selfCollide>false</selfCollide>
    <turnGravityOff>true</turnGravityOff>
  </gazebo>
  <gazebo reference="RThumb1">
    <mu1>0.5</mu1>
    <mu2>0.5</mu2>
    <selfCollide>false</selfCollide>
    <turnGravityOff>true</turnGravityOff>
  </gazebo>
  <gazebo reference="RThumb2">
    <mu1>0.5</mu1>
    <mu2>0.5</mu2>
    <selfCollide>false</selfCollide>
    <turnGravityOff>true</turnGravityOff>
  </gazebo>
  <joint name="torso-imu" type="fixed">
    <parent link="torso"/>
    <child link="imu"/>
    <!-- Accelerometer -->
    <origin rpy="0 0 0" xyz="-0.008 0.00606 0.027"/>
    <!-- Gyrometer -->
    <!-- <origin xyz="-0.008 0.006 0.029" rpy="0 0 0"/> -->
  </joint>
  <link name="imu"/>
  <joint name="LFinger1" type="revolute">
    <parent link="l_wrist"/>
    <child link="LFinger11"/>
    <origin rpy="0 0 0" xyz="0.06907 0.01157 -0.00304"/>
    <axis xyz="0 1 0"/>
    <mimic joint="LHand" multiplier="-0.785398163398" offset="0.785398163398"/>
    <limit effort="10.0" lower="0.0" upper="0.785398163398" velocity="3.0"/>
  </joint>
  <link name="LFinger11">
    <visual>
      <origin rpy="0 -0 0" xyz="0 0 0"/>
      <geometry>
        <mesh filename="package://nao_meshes/meshes/V40/visual/LFinger11.dae" scale="0.1 0.1 0.1"/>
      </geometry>
    </visual>
    <collision>
      <origin rpy="0 -0 0" xyz="0 0 0"/>
      <geometry>
        <mesh filename="package://nao_meshes/meshes/V40/collision/LFinger11.stl" scale="0.1 0.1 0.1"/>
      </geometry>
    </collision>
    <inertial>
      <mass value="0.2e-5"/>
      <origin xyz="0 0 0"/>
      <inertia ixx="1e-9" ixy="0" ixz="0" iyy="1e-9" iyz="0" izz="1e-9"/>
    </inertial>
  </link>
  <joint name="LFinger1_1" type="revolute">
    <parent link="LFinger11"/>
    <child link="LFinger12"/>
    <origin rpy="0 0 0" xyz="0.01436 0 0"/>
    <axis xyz="0 1 0"/>
    <mimic joint="LHand" multiplier="-0.785398163398" offset="0.785398163398"/>
    <limit effort="10.0" lower="0.0" upper="0.785398163398" velocity="3.0"/>
  </joint>
  <link name="LFinger12">
    <visual>
      <origin rpy="0 -0 0" xyz="0 0 0"/>
      <geometry>
        <mesh filename="package://nao_meshes/meshes/V40/visual/LFinger12.dae" scale="0.1 0.1 0.1"/>
      </geometry>
    </visual>
    <collision>
      <origin rpy="0 -0 0" xyz="0 0 0"/>
      <geometry>
        <mesh filename="package://nao_meshes/meshes/V40/collision/LFinger12.stl" scale="0.1 0.1 0.1"/>
      </geometry>
    </collision>
    <inertial>
      <mass value="0.2e-5"/>
      <origin xyz="0 0 0"/>
      <inertia ixx="1e-9" ixy="0" ixz="0" iyy="1e-9" iyz="0" izz="1e-9"/>
    </inertial>
  </link>
  <joint name="LFinger1_2" type="revolute">
    <parent link="LFinger12"/>
    <child link="LFinger13"/>
    <origin rpy="0 0 0" xyz="0.01436 0 0"/>
    <axis xyz="0 1 0"/>
    <mimic joint="LHand" multiplier="-0.785398163398" offset="0.785398163398"/>
    <limit effort="10.0" lower="0.0" upper="0.785398163398" velocity="3.0"/>
  </joint>
  <link name="LFinger13">
    <visual>
      <origin rpy="0 -0 0" xyz="0 0 0"/>
      <geometry>
        <mesh filename="package://nao_meshes/meshes/V40/visual/LFinger13.dae" scale="0.1 0.1 0.1"/>
      </geometry>
    </visual>
    <collision>
      <origin rpy="0 -0 0" xyz="0 0 0"/>
      <geometry>
        <mesh filename="package://nao_meshes/meshes/V40/collision/LFinger13.stl" scale="0.1 0.1 0.1"/>
      </geometry>
    </collision>
    <inertial>
      <mass value="0.2e-5"/>
      <origin xyz="0 0 0"/>
      <inertia ixx="1e-9" ixy="0" ixz="0" iyy="1e-9" iyz="0" izz="1e-9"/>
    </inertial>
  </link>
  <joint name="LFinger2" type="revolute">
    <parent link="l_wrist"/>
    <child link="LFinger21"/>
    <origin rpy="0 0 0" xyz="0.06907 -0.01157 -0.00304"/>
    <axis xyz="0 1 0"/>
    <mimic joint="LHand" multiplier="-0.785398163398" offset="0.785398163398"/>
    <limit effort="10.0" lower="0.0" upper="0.785398163398" velocity="3.0"/>
  </joint>
  <link name="LFinger21">
    <visual>
      <origin rpy="0 -0 0" xyz="0 0 0"/>
      <geometry>
        <mesh filename="package://nao_meshes/meshes/V40/visual/LFinger21.dae" scale="0.1 0.1 0.1"/>
      </geometry>
    </visual>
    <collision>
      <origin rpy="0 -0 0" xyz="0 0 0"/>
      <geometry>
        <mesh filename="package://nao_meshes/meshes/V40/collision/LFinger21.stl" scale="0.1 0.1 0.1"/>
      </geometry>
    </collision>
    <inertial>
      <mass value="0.2e-5"/>
      <origin xyz="0 0 0"/>
      <inertia ixx="1e-9" ixy="0" ixz="0" iyy="1e-9" iyz="0" izz="1e-9"/>
    </inertial>
  </link>
  <joint name="LFinger2_1" type="revolute">
    <parent link="LFinger21"/>
    <child link="LFinger22"/>
    <origin rpy="0 0 0" xyz="0.01436 0 0"/>
    <axis xyz="0 1 0"/>
    <mimic joint="LHand" multiplier="-0.785398163398" offset="0.785398163398"/>
    <limit effort="10.0" lower="0.0" upper="0.785398163398" velocity="3.0"/>
  </joint>
  <link name="LFinger22">
    <visual>
      <origin rpy="0 -0 0" xyz="0 0 0"/>
      <geometry>
        <mesh filename="package://nao_meshes/meshes/V40/visual/LFinger22.dae" scale="0.1 0.1 0.1"/>
      </geometry>
    </visual>
    <collision>
      <origin rpy="0 -0 0" xyz="0 0 0"/>
      <geometry>
        <mesh filename="package://nao_meshes/meshes/V40/collision/LFinger22.stl" scale="0.1 0.1 0.1"/>
      </geometry>
    </collision>
    <inertial>
      <mass value="0.2e-5"/>
      <origin xyz="0 0 0"/>
      <inertia ixx="1e-9" ixy="0" ixz="0" iyy="1e-9" iyz="0" izz="1e-9"/>
    </inertial>
  </link>
  <joint name="LFinger2_2" type="revolute">
    <parent link="LFinger22"/>
    <child link="LFinger23"/>
    <origin rpy="0 0 0" xyz="0.01436 0 0"/>
    <axis xyz="0 1 0"/>
    <mimic joint="LHand" multiplier="-0.785398163398" offset="0.785398163398"/>
    <limit effort="10.0" lower="0.0" upper="0.785398163398" velocity="3.0"/>
  </joint>
  <link name="LFinger23">
    <visual>
      <origin rpy="0 -0 0" xyz="0 0 0"/>
      <geometry>
        <mesh filename="package://nao_meshes/meshes/V40/visual/LFinger23.dae" scale="0.1 0.1 0.1"/>
      </geometry>
    </visual>
    <collision>
      <origin rpy="0 -0 0" xyz="0 0 0"/>
      <geometry>
        <mesh filename="package://nao_meshes/meshes/V40/collision/LFinger23.stl" scale="0.1 0.1 0.1"/>
      </geometry>
    </collision>
    <inertial>
      <mass value="0.2e-5"/>
      <origin xyz="0 0 0"/>
      <inertia ixx="1e-9" ixy="0" ixz="0" iyy="1e-9" iyz="0" izz="1e-9"/>
    </inertial>
  </link>
  <joint name="RFinger1" type="revolute">
    <parent link="r_wrist"/>
    <child link="RFinger11"/>
    <origin rpy="0 0 0" xyz="0.06907 0.01157 -0.00304"/>
    <axis xyz="0 1 0"/>
    <mimic joint="RHand" multiplier="-0.785398163398" offset="0.785398163398"/>
    <limit effort="10.0" lower="0.0" upper="0.785398163398" velocity="3.0"/>
  </joint>
  <link name="RFinger11">
    <visual>
      <origin rpy="0 -0 0" xyz="0 0 0"/>
      <geometry>
        <mesh filename="package://nao_meshes/meshes/V40/visual/RFinger11.dae" scale="0.1 0.1 0.1"/>
      </geometry>
    </visual>
    <collision>
      <origin rpy="0 -0 0" xyz="0 0 0"/>
      <geometry>
        <mesh filename="package://nao_meshes/meshes/V40/collision/RFinger11.stl" scale="0.1 0.1 0.1"/>
      </geometry>
    </collision>
    <inertial>
      <mass value="0.2e-5"/>
      <origin xyz="0 0 0"/>
      <inertia ixx="1e-9" ixy="0" ixz="0" iyy="1e-9" iyz="0" izz="1e-9"/>
    </inertial>
  </link>
  <joint name="RFinger1_1" type="revolute">
    <parent link="RFinger11"/>
    <child link="RFinger12"/>
    <origin rpy="0 0 0" xyz="0.01436 0 0"/>
    <axis xyz="0 1 0"/>
    <mimic joint="RHand" multiplier="-0.785398163398" offset="0.785398163398"/>
    <limit effort="10.0" lower="0.0" upper="0.785398163398" velocity="3.0"/>
  </joint>
  <link name="RFinger12">
    <visual>
      <origin rpy="0 -0 0" xyz="0 0 0"/>
      <geometry>
        <mesh filename="package://nao_meshes/meshes/V40/visual/RFinger12.dae" scale="0.1 0.1 0.1"/>
      </geometry>
    </visual>
    <collision>
      <origin rpy="0 -0 0" xyz="0 0 0"/>
      <geometry>
        <mesh filename="package://nao_meshes/meshes/V40/collision/RFinger12.stl" scale="0.1 0.1 0.1"/>
      </geometry>
    </collision>
    <inertial>
      <mass value="0.2e-5"/>
      <origin xyz="0 0 0"/>
      <inertia ixx="1e-9" ixy="0" ixz="0" iyy="1e-9" iyz="0" izz="1e-9"/>
    </inertial>
  </link>
  <joint name="RFinger1_2" type="revolute">
    <parent link="RFinger12"/>
    <child link="RFinger13"/>
    <origin rpy="0 0 0" xyz="0.01436 0 0"/>
    <axis xyz="0 1 0"/>
    <mimic joint="RHand" multiplier="-0.785398163398" offset="0.785398163398"/>
    <limit effort="10.0" lower="0.0" upper="0.785398163398" velocity="3.0"/>
  </joint>
  <link name="RFinger13">
    <visual>
      <origin rpy="0 -0 0" xyz="0 0 0"/>
      <geometry>
        <mesh filename="package://nao_meshes/meshes/V40/visual/RFinger13.dae" scale="0.1 0.1 0.1"/>
      </geometry>
    </visual>
    <collision>
      <origin rpy="0 -0 0" xyz="0 0 0"/>
      <geometry>
        <mesh filename="package://nao_meshes/meshes/V40/collision/RFinger13.stl" scale="0.1 0.1 0.1"/>
      </geometry>
    </collision>
    <inertial>
      <mass value="0.2e-5"/>
      <origin xyz="0 0 0"/>
      <inertia ixx="1e-9" ixy="0" ixz="0" iyy="1e-9" iyz="0" izz="1e-9"/>
    </inertial>
  </link>
  <joint name="RFinger2" type="revolute">
    <parent link="r_wrist"/>
    <child link="RFinger21"/>
    <origin rpy="0 0 0" xyz="0.06907 -0.01157 -0.00304"/>
    <axis xyz="0 1 0"/>
    <mimic joint="RHand" multiplier="-0.785398163398" offset="0.785398163398"/>
    <limit effort="10.0" lower="0.0" upper="0.785398163398" velocity="3.0"/>
  </joint>
  <link name="RFinger21">
    <visual>
      <origin rpy="0 -0 0" xyz="0 0 0"/>
      <geometry>
        <mesh filename="package://nao_meshes/meshes/V40/visual/RFinger21.dae" scale="0.1 0.1 0.1"/>
      </geometry>
    </visual>
    <collision>
      <origin rpy="0 -0 0" xyz="0 0 0"/>
      <geometry>
        <mesh filename="package://nao_meshes/meshes/V40/collision/RFinger21.stl" scale="0.1 0.1 0.1"/>
      </geometry>
    </collision>
    <inertial>
      <mass value="0.2e-5"/>
      <origin xyz="0 0 0"/>
      <inertia ixx="1e-9" ixy="0" ixz="0" iyy="1e-9" iyz="0" izz="1e-9"/>
    </inertial>
  </link>
  <joint name="RFinger2_1" type="revolute">
    <parent link="RFinger21"/>
    <child link="RFinger22"/>
    <origin rpy="0 0 0" xyz="0.01436 0 0"/>
    <axis xyz="0 1 0"/>
    <mimic joint="RHand" multiplier="-0.785398163398" offset="0.785398163398"/>
    <limit effort="10.0" lower="0.0" upper="0.785398163398" velocity="3.0"/>
  </joint>
  <link name="RFinger22">
    <visual>
      <origin rpy="0 -0 0" xyz="0 0 0"/>
      <geometry>
        <mesh filename="package://nao_meshes/meshes/V40/visual/RFinger22.dae" scale="0.1 0.1 0.1"/>
      </geometry>
    </visual>
    <collision>
      <origin rpy="0 -0 0" xyz="0 0 0"/>
      <geometry>
        <mesh filename="package://nao_meshes/meshes/V40/collision/RFinger22.stl" scale="0.1 0.1 0.1"/>
      </geometry>
    </collision>
    <inertial>
      <mass value="0.2e-5"/>
      <origin xyz="0 0 0"/>
      <inertia ixx="1e-9" ixy="0" ixz="0" iyy="1e-9" iyz="0" izz="1e-9"/>
    </inertial>
  </link>
  <joint name="RFinger2_2" type="revolute">
    <parent link="RFinger22"/>
    <child link="RFinger23"/>
    <origin rpy="0 0 0" xyz="0.01436 0 0"/>
    <axis xyz="0 1 0"/>
    <mimic joint="RHand" multiplier="-0.785398163398" offset="0.785398163398"/>
    <limit effort="10.0" lower="0.0" upper="0.785398163398" velocity="3.0"/>
  </joint>
  <link name="RFinger23">
    <visual>
      <origin rpy="0 -0 0" xyz="0 0 0"/>
      <geometry>
        <mesh filename="package://nao_meshes/meshes/V40/visual/RFinger23.dae" scale="0.1 0.1 0.1"/>
      </geometry>
    </visual>
    <collision>
      <origin rpy="0 -0 0" xyz="0 0 0"/>
      <geometry>
        <mesh filename="package://nao_meshes/meshes/V40/collision/RFinger23.stl" scale="0.1 0.1 0.1"/>
      </geometry>
    </collision>
    <inertial>
      <mass value="0.2e-5"/>
      <origin xyz="0 0 0"/>
      <inertia ixx="1e-9" ixy="0" ixz="0" iyy="1e-9" iyz="0" izz="1e-9"/>
    </inertial>
  </link>
  <joint name="LThumb1_joint" type="revolute">
    <parent link="l_wrist"/>
    <child link="LThumb1"/>
    <origin rpy="3.14159265359 0.785398163398 0" xyz="0.04895 0 -0.02638"/>
    <axis xyz="0 1 0"/>
    <mimic joint="LHand" multiplier="-0.785398163398" offset="0.785398163398"/>
    <limit effort="10.0" lower="0.0" upper="0.785398163398" velocity="3.0"/>
  </joint>
  <link name="LThumb1">
    <visual>
      <origin rpy="0 -0 0" xyz="0 0 0"/>
      <geometry>
        <mesh filename="package://nao_meshes/meshes/V40/visual/LThumb1.dae" scale="0.1 0.1 0.1"/>
      </geometry>
    </visual>
    <collision>
      <origin rpy="0 -0 0" xyz="0 0 0"/>
      <geometry>
        <mesh filename="package://nao_meshes/meshes/V40/collision/LThumb1.stl" scale="0.1 0.1 0.1"/>
      </geometry>
    </collision>
    <inertial>
      <mass value="0.2e-5"/>
      <origin xyz="0 0 0"/>
      <inertia ixx="1e-9" ixy="0" ixz="0" iyy="1e-9" iyz="0" izz="1e-9"/>
    </inertial>
  </link>
  <joint name="LThumb1_2" type="revolute">
    <parent link="LThumb1"/>
    <child link="LThumb2"/>
    <origin rpy="0 0 0" xyz="0.01436 0 0"/>
    <axis xyz="0 1 0"/>
    <mimic joint="LHand" multiplier="-0.785398163398" offset="0.785398163398"/>
    <limit effort="10.0" lower="0.0" upper="0.785398163398" velocity="3.0"/>
  </joint>
  <link name="LThumb2">
    <visual>
      <origin rpy="0 -0 0" xyz="0 0 0"/>
      <geometry>
        <mesh filename="package://nao_meshes/meshes/V40/visual/LThumb2.dae" scale="0.1 0.1 0.1"/>
      </geometry>
    </visual>
    <collision>
      <origin rpy="0 -0 0" xyz="0 0 0"/>
      <geometry>
        <mesh filename="package://nao_meshes/meshes/V40/collision/LThumb2.stl" scale="0.1 0.1 0.1"/>
      </geometry>
    </collision>
    <inertial>
      <mass value="0.2e-5"/>
      <origin xyz="0 0 0"/>
      <inertia ixx="1e-9" ixy="0" ixz="0" iyy="1e-9" iyz="0" izz="1e-9"/>
    </inertial>
  </link>
  <joint name="RThumb1_joint" type="revolute">
    <parent link="r_wrist"/>
    <child link="RThumb1"/>
    <origin rpy="3.14159265359 0.785398163398 0" xyz="0.04895 0 -0.02638"/>
    <axis xyz="0 1 0"/>
    <mimic joint="RHand" multiplier="-0.785398163398" offset="0.785398163398"/>
    <limit effort="10.0" lower="0.0" upper="0.785398163398" velocity="3.0"/>
  </joint>
  <link name="RThumb1">
    <visual>
      <origin rpy="0 -0 0" xyz="0 0 0"/>
      <geometry>
        <mesh filename="package://nao_meshes/meshes/V40/visual/RThumb1.dae" scale="0.1 0.1 0.1"/>
      </geometry>
    </visual>
    <collision>
      <origin rpy="0 -0 0" xyz="0 0 0"/>
      <geometry>
        <mesh filename="package://nao_meshes/meshes/V40/collision/RThumb1.stl" scale="0.1 0.1 0.1"/>
      </geometry>
    </collision>
    <inertial>
      <mass value="0.2e-5"/>
      <origin xyz="0 0 0"/>
      <inertia ixx="1e-9" ixy="0" ixz="0" iyy="1e-9" iyz="0" izz="1e-9"/>
    </inertial>
  </link>
  <joint name="RThumb1_2" type="revolute">
    <parent link="RThumb1"/>
    <child link="RThumb2"/>
    <origin rpy="0 0 0" xyz="0.01436 0 0"/>
    <axis xyz="0 1 0"/>
    <mimic joint="RHand" multiplier="-0.785398163398" offset="0.785398163398"/>
    <limit effort="10.0" lower="0.0" upper="0.785398163398" velocity="3.0"/>
  </joint>
  <link name="RThumb2">
    <visual>
      <origin rpy="0 -0 0" xyz="0 0 0"/>
      <geometry>
        <mesh filename="package://nao_meshes/meshes/V40/visual/RThumb2.dae" scale="0.1 0.1 0.1"/>
      </geometry>
    </visual>
    <collision>
      <origin rpy="0 -0 0" xyz="0 0 0"/>
      <geometry>
        <mesh filename="package://nao_meshes/meshes/V40/collision/RThumb2.stl" scale="0.1 0.1 0.1"/>
      </geometry>
    </collision>
    <inertial>
      <mass value="0.2e-5"/>
      <origin xyz="0 0 0"/>
      <inertia ixx="1e-9" ixy="0" ixz="0" iyy="1e-9" iyz="0" izz="1e-9"/>
    </inertial>
  </link>
  <joint name="HeadYaw" type="revolute">
    <parent link="torso"/>
    <child link="Neck"/>
    <origin rpy="0 0 0" xyz="0 0 0.1265"/>
    <axis xyz="0 0 1.0"/>
    <limit effort="1.2" lower="-2.08567" upper="2.08567" velocity="8.26797"/>
  </joint>
  <link name="Neck">
    <inertial>
      <mass value="0.0593"/>
      <inertia ixx="6.18031e-05" ixy="-2.05e-09" ixz="-4.948e-08" iyy="6.28186e-05" iyz="-5.067e-08" izz="5.43977e-06"/>
      <origin rpy="0 0 0" xyz="-2e-05 0 -0.02556"/>
    </inertial>
    <visual>
      <geometry>
        <mesh filename="package://nao_meshes/meshes/V40/visual/HeadYaw.dae" scale="0.1 0.1 0.1"/>
      </geometry>
    </visual>
    <collision>
      <geometry>
        <mesh filename="package://nao_meshes/meshes/V40/collision/HeadYaw.stl" scale="0.1 0.1 0.1"/>
      </geometry>
    </collision>
  </link>
  <joint name="HeadPitch" type="revolute">
    <parent link="Neck"/>
    <child link="Head"/>
    <origin rpy="0 0 0" xyz="0 0 0"/>
    <axis xyz="0 1.0 0"/>
    <limit effort="1.2" lower="-0.671952" upper="0.514872" velocity="7.19407"/>
  </joint>
  <link name="Head">
    <inertial>
      <mass value="0.52065"/>
      <inertia ixx="0.00226587" ixy="7.87181e-06" ixz="-1.19265e-05" iyy="0.00226421" iyz="-2.31846e-06" izz="0.000873733"/>
      <origin rpy="0 0 0" xyz="0.0012 0 0.05353"/>
    </inertial>
    <visual>
      <geometry>
        <mesh filename="package://nao_meshes/meshes/V40/visual/HeadPitch.dae" scale="0.1 0.1 0.1"/>
      </geometry>
    </visual>
    <collision>
      <geometry>
        <mesh filename="package://nao_meshes/meshes/V40/collision/HeadPitch.stl" scale="0.1 0.1 0.1"/>
      </geometry>
    </collision>
  </link>
  <joint name="gaze_joint" type="fixed">
    <parent link="Head"/>
    <child link="gaze"/>
    <origin rpy="0 0 0" xyz="0.0539 0 0.0679"/>
  </joint>
  <link name="gaze"/>
  <joint name="LHipYawPitch" type="revolute">
    <parent link="torso"/>
    <child link="LPelvis"/>
    <origin rpy="0 0 0" xyz="0 0.05 -0.085"/>
    <axis xyz="0 0.707106 -0.707106"/>
    <limit effort="3.2" lower="-1.14529" upper="0.740718" velocity="4.16174"/>
  </joint>
  <link name="LPelvis">
    <inertial>
      <mass value="0.07117"/>
      <inertia ixx="8.99716e-05" ixy="-5.00214e-06" ixz="1.27355e-05" iyy="0.000105523" iyz="2.77007e-05" izz="6.68838e-05"/>
      <origin rpy="0 0 0" xyz="-0.00766 -0.012 0.02717"/>
    </inertial>
    <visual>
      <geometry>
        <mesh filename="package://nao_meshes/meshes/V40/visual/LHipYawPitch.dae" scale="0.1 0.1 0.1"/>
      </geometry>
    </visual>
    <collision>
      <geometry>
        <mesh filename="package://nao_meshes/meshes/V40/collision/LHipYawPitch.stl" scale="0.1 0.1 0.1"/>
      </geometry>
    </collision>
  </link>
  <joint name="LHipRoll" type="revolute">
    <parent link="LPelvis"/>
    <child link="LHip"/>
    <origin rpy="0 0 0" xyz="0 0 0"/>
    <axis xyz="1.0 0 0"/>
    <limit effort="3.2" lower="-0.379435" upper="0.79046" velocity="4.16174"/>
  </joint>
  <link name="LHip">
    <inertial>
      <mass value="0.1353"/>
      <inertia ixx="2.79131e-05" ixy="4.982e-08" ixz="-5.30968e-06" iyy="0.000101469" iyz="0" izz="0.000292094"/>
      <origin rpy="0 0 0" xyz="-0.01649 0.00029 -0.00475"/>
    </inertial>
    <visual>
      <geometry>
        <mesh filename="package://nao_meshes/meshes/V40/visual/LHipRoll.dae" scale="0.1 0.1 0.1"/>
      </geometry>
    </visual>
    <collision>
      <geometry>
        <mesh filename="package://nao_meshes/meshes/V40/collision/LHipRoll.stl" scale="0.1 0.1 0.1"/>
      </geometry>
    </collision>
  </link>
  <joint name="LHipPitch" type="revolute">
    <parent link="LHip"/>
    <child link="LThigh"/>
    <origin rpy="0 0 0" xyz="0 0 0"/>
    <axis xyz="0 1.0 0"/>
    <limit effort="3.2" lower="-1.53589" upper="0.48398" velocity="6.40239"/>
  </joint>
  <link name="LThigh">
    <inertial>
      <mass value="0.39798"/>
      <inertia ixx="0.00166559" ixy="4.3251e-07" ixz="8.25051e-05" iyy="0.001625" iyz="3.17428e-05" izz="0.000304929"/>
      <origin rpy="0 0 0" xyz="0.00131 0.00201 -0.05386"/>
    </inertial>
    <visual>
      <geometry>
        <mesh filename="package://nao_meshes/meshes/V40/visual/LHipPitch.dae" scale="0.1 0.1 0.1"/>
      </geometry>
    </visual>
    <collision>
      <geometry>
        <mesh filename="package://nao_meshes/meshes/V40/collision/LHipPitch.stl" scale="0.1 0.1 0.1"/>
      </geometry>
    </collision>
  </link>
  <joint name="LKneePitch" type="revolute">
    <parent link="LThigh"/>
    <child link="LTibia"/>
    <origin rpy="0 0 0" xyz="0 0 -0.1"/>
    <axis xyz="0 1.0 0"/>
    <limit effort="3.2" lower="-0.0923279" upper="2.11255" velocity="6.40239"/>
  </joint>
  <link name="LTibia">
    <inertial>
      <mass value="0.29159"/>
      <inertia ixx="0.00115383" ixy="7.7529e-07" ixz="3.23128e-05" iyy="0.00110378" iyz="4.39673e-05" izz="0.00018861"/>
      <origin rpy="0 0 0" xyz="0.00422 0.00252 -0.04868"/>
    </inertial>
    <visual>
      <geometry>
        <mesh filename="package://nao_meshes/meshes/V40/visual/LKneePitch.dae" scale="0.1 0.1 0.1"/>
      </geometry>
    </visual>
    <collision>
      <geometry>
        <mesh filename="package://nao_meshes/meshes/V40/collision/LKneePitch.stl" scale="0.1 0.1 0.1"/>
      </geometry>
    </collision>
  </link>
  <joint name="LAnklePitch" type="revolute">
    <parent link="LTibia"/>
    <child link="l_ankle"/>
    <origin rpy="0 0 0" xyz="0 0 -0.1029"/>
    <axis xyz="0 1.0 0"/>
    <limit effort="3.2" lower="-1.18944" upper="0.922581" velocity="6.40239"/>
  </joint>
  <link name="l_ankle">
    <inertial>
      <mass value="0.13892"/>
      <inertia ixx="3.88258e-05" ixy="-4.942e-08" ixz="2.21321e-06" iyy="7.21158e-05" iyz="6.74e-09" izz="5.35199e-05"/>
      <origin rpy="0 0 0" xyz="0.00142 0.00028 0.00638"/>
    </inertial>
    <visual>
      <geometry>
        <mesh filename="package://nao_meshes/meshes/V40/visual/LAnklePitch.dae" scale="0.1 0.1 0.1"/>
      </geometry>
    </visual>
    <collision>
      <geometry>
        <mesh filename="package://nao_meshes/meshes/V40/collision/LAnklePitch.stl" scale="0.1 0.1 0.1"/>
      </geometry>
    </collision>
  </link>
  <joint name="LAnkleRoll" type="revolute">
    <parent link="l_ankle"/>
    <child link="l_sole"/>
    <origin rpy="0 0 0" xyz="0 0 0"/>
    <axis xyz="1.0 0 0"/>
    <limit effort="3.2" lower="-0.397761" upper="0.768992" velocity="4.16174"/>
  </joint>
  <link name="l_sole">
    <inertial>
      <mass value="0.16175"/>
      <inertia ixx="0.000269612" ixy="-5.8769e-06" ixz="0.000139244" iyy="0.000643878" iyz="1.8871e-05" izz="0.000525192"/>
      <origin rpy="0 0 0" xyz="0.0254 0.00332 -0.03241"/>
    </inertial>
    <visual>
      <geometry>
        <mesh filename="package://nao_meshes/meshes/V40/visual/LAnkleRoll.dae" scale="0.1 0.1 0.1"/>
      </geometry>
    </visual>
    <collision>
      <geometry>
        <mesh filename="package://nao_meshes/meshes/V40/collision/LAnkleRoll.stl" scale="0.1 0.1 0.1"/>
      </geometry>
    </collision>
  </link>
  <joint name="RHipYawPitch" type="revolute">
    <parent link="torso"/>
    <child link="RPelvis"/>
    <origin rpy="0 0 0" xyz="0 -0.05 -0.085"/>
    <axis xyz="0 0.707106 0.707106"/>
    <limit effort="3.2" lower="-1.14529" upper="0.740718" velocity="4.16174"/>
  </joint>
  <link name="RPelvis">
    <inertial>
      <mass value="0.07117"/>
      <inertia ixx="8.99716e-05" ixy="5.00214e-06" ixz="1.27355e-05" iyy="0.000105523" iyz="-2.77007e-05" izz="6.68838e-05"/>
      <origin rpy="0 0 0" xyz="-0.00766 0.012 0.02717"/>
    </inertial>
    <visual>
      <geometry>
        <mesh filename="package://nao_meshes/meshes/V40/visual/RHipYawPitch.dae" scale="0.1 0.1 0.1"/>
      </geometry>
    </visual>
    <collision>
      <geometry>
        <mesh filename="package://nao_meshes/meshes/V40/collision/RHipYawPitch.stl" scale="0.1 0.1 0.1"/>
      </geometry>
    </collision>
  </link>
  <joint name="RHipRoll" type="revolute">
    <parent link="RPelvis"/>
    <child link="RHip"/>
    <origin rpy="0 0 0" xyz="0 0 0"/>
    <axis xyz="1.0 0 0"/>
    <limit effort="3.2" lower="-0.79046" upper="0.379435" velocity="4.16174"/>
  </joint>
  <link name="RHip">
    <inertial>
      <mass value="0.1353"/>
      <inertia ixx="2.79131e-05" ixy="-4.982e-08" ixz="-5.30968e-06" iyy="0.000101469" iyz="0" izz="0.000292094"/>
      <origin rpy="0 0 0" xyz="-0.01649 -0.00029 -0.00475"/>
    </inertial>
    <visual>
      <geometry>
        <mesh filename="package://nao_meshes/meshes/V40/visual/RHipRoll.dae" scale="0.1 0.1 0.1"/>
      </geometry>
    </visual>
    <collision>
      <geometry>
        <mesh filename="package://nao_meshes/meshes/V40/collision/RHipRoll.stl" scale="0.1 0.1 0.1"/>
      </geometry>
    </collision>
  </link>
  <joint name="RHipPitch" type="revolute">
    <parent link="RHip"/>
    <child link="RThigh"/>
    <origin rpy="0 0 0" xyz="0 0 0"/>
    <axis xyz="0 1.0 0"/>
    <limit effort="3.2" lower="-1.53589" upper="0.48398" velocity="6.40239"/>
  </joint>
  <link name="RThigh">
    <inertial>
      <mass value="0.39798"/>
      <inertia ixx="0.00166559" ixy="-4.3251e-07" ixz="8.25051e-05" iyy="0.001625" iyz="-3.17428e-05" izz="0.000304929"/>
      <origin rpy="0 0 0" xyz="0.00131 -0.00201 -0.05386"/>
    </inertial>
    <visual>
      <geometry>
        <mesh filename="package://nao_meshes/meshes/V40/visual/RHipPitch.dae" scale="0.1 0.1 0.1"/>
      </geometry>
    </visual>
    <collision>
      <geometry>
        <mesh filename="package://nao_meshes/meshes/V40/collision/RHipPitch.stl" scale="0.1 0.1 0.1"/>
      </geometry>
    </collision>
  </link>
  <joint name="RKneePitch" type="revolute">
    <parent link="RThigh"/>
    <child link="RTibia"/>
    <origin rpy="0 0 0" xyz="0 0 -0.1"/>
    <axis xyz="0 1.0 0"/>
    <limit effort="3.2" lower="-0.0923279" upper="2.11255" velocity="6.40239"/>
  </joint>
  <link name="RTibia">
    <inertial>
      <mass value="0.29159"/>
      <inertia ixx="0.00115383" ixy="-7.7529e-07" ixz="3.23128e-05" iyy="0.00110378" iyz="-4.39673e-05" izz="0.00018861"/>
      <origin rpy="0 0 0" xyz="0.00422 -0.00252 -0.04868"/>
    </inertial>
    <visual>
      <geometry>
        <mesh filename="package://nao_meshes/meshes/V40/visual/RKneePitch.dae" scale="0.1 0.1 0.1"/>
      </geometry>
    </visual>
    <collision>
      <geometry>
        <mesh filename="package://nao_meshes/meshes/V40/collision/RKneePitch.stl" scale="0.1 0.1 0.1"/>
      </geometry>
    </collision>
  </link>
  <joint name="RAnklePitch" type="revolute">
    <parent link="RTibia"/>
    <child link="r_ankle"/>
    <origin rpy="0 0 0" xyz="0 0 -0.1029"/>
    <axis xyz="0 1.0 0"/>
    <limit effort="3.2" lower="-1.1863" upper="0.932006" velocity="6.40239"/>
  </joint>
  <link name="r_ankle">
    <inertial>
      <mass value="0.13892"/>
      <inertia ixx="3.88258e-05" ixy="4.942e-08" ixz="2.21321e-06" iyy="7.21158e-05" iyz="-6.74e-09" izz="5.35199e-05"/>
      <origin rpy="0 0 0" xyz="0.00142 -0.00028 0.00638"/>
    </inertial>
    <visual>
      <geometry>
        <mesh filename="package://nao_meshes/meshes/V40/visual/RAnklePitch.dae" scale="0.1 0.1 0.1"/>
      </geometry>
    </visual>
    <collision>
      <geometry>
        <mesh filename="package://nao_meshes/meshes/V40/collision/RAnklePitch.stl" scale="0.1 0.1 0.1"/>
      </geometry>
    </collision>
  </link>
  <joint name="RAnkleRoll" type="revolute">
    <parent link="r_ankle"/>
    <child link="r_sole"/>
    <origin rpy="0 0 0" xyz="0 0 0"/>
    <axis xyz="1.0 0 0"/>
    <limit effort="3.2" lower="-0.768992" upper="0.397935" velocity="4.16174"/>
  </joint>
  <link name="r_sole">
    <inertial>
      <mass value="0.16175"/>
      <inertia ixx="0.000269612" ixy="5.8769e-06" ixz="0.000139244" iyy="0.000643878" iyz="-1.8871e-05" izz="0.000525192"/>
      <origin rpy="0 0 0" xyz="0.0254 -0.00332 -0.03241"/>
    </inertial>
    <visual>
      <geometry>
        <mesh filename="package://nao_meshes/meshes/V40/visual/RAnkleRoll.dae" scale="0.1 0.1 0.1"/>
      </geometry>
    </visual>
    <collision>
      <geometry>
        <mesh filename="package://nao_meshes/meshes/V40/collision/RAnkleRoll.stl" scale="0.1 0.1 0.1"/>
      </geometry>
    </collision>
  </link>
  <link name="base_link"/>
  <joint name="base_joint" type="fixed">
    <parent link="base_link"/>
    <child link="torso"/>
    <origin rpy="0 0 0" xyz="0 0 0"/>
  </joint>
  <link name="torso">
    <inertial>
      <mass value="1.03948"/>
      <inertia ixx="0.00496742" ixy="1.2474e-05" ixz="0.000164468" iyy="0.00479135" iyz="-2.47767e-05" izz="0.00159785"/>
      <origin rpy="0 0 0" xyz="-0.00415 0 0.04258"/>
    </inertial>
    <visual>
      <geometry>
        <mesh filename="package://nao_meshes/meshes/V40/visual/Torso.dae" scale="0.1 0.1 0.1"/>
      </geometry>
    </visual>
    <collision>
      <geometry>
        <mesh filename="package://nao_meshes/meshes/V40/collision/Torso.stl" scale="0.1 0.1 0.1"/>
      </geometry>
    </collision>
  </link>
  <joint name="LShoulderPitch" type="revolute">
    <parent link="torso"/>
    <child link="LShoulder"/>
    <origin rpy="0 0 0" xyz="0 0.098 0.1"/>
    <axis xyz="0 1.0 0"/>
    <limit effort="1.2" lower="-2.08567" upper="2.08567" velocity="8.26797"/>
  </joint>
  <link name="LShoulder">
    <inertial>
      <mass value="0.06996"/>
      <inertia ixx="7.1025e-05" ixy="-2.02467e-06" ixz="1.722e-08" iyy="1.4058e-05" iyz="8.41e-09" izz="7.3166e-05"/>
      <origin rpy="0 0 0" xyz="-0.00178 -0.02496 0.00018"/>
    </inertial>
    <visual>
      <geometry>
        <mesh filename="package://nao_meshes/meshes/V40/visual/LShoulderPitch.dae" scale="0.1 0.1 0.1"/>
      </geometry>
    </visual>
    <collision>
      <geometry>
        <mesh filename="package://nao_meshes/meshes/V40/collision/LShoulderPitch.stl" scale="0.1 0.1 0.1"/>
      </geometry>
    </collision>
  </link>
  <joint name="LShoulderRoll" type="revolute">
    <parent link="LShoulder"/>
    <child link="LBicep"/>
    <origin rpy="0 0 0" xyz="0 0 0"/>
    <axis xyz="0 0 1.0"/>
    <limit effort="1.2" lower="-0.314159" upper="1.32645" velocity="7.19407"/>
  </joint>
  <link name="LBicep">
    <inertial>
      <mass value="0.12309"/>
      <inertia ixx="8.22841e-05" ixy="-3.97806e-05" ixz="-7.52601e-06" iyy="0.000290014" iyz="-1.52945e-06" izz="0.000268423"/>
      <origin rpy="0 0 0" xyz="0.01885 0.00577 0.00065"/>
    </inertial>
    <visual>
      <geometry>
        <mesh filename="package://nao_meshes/meshes/V40/visual/LShoulderRoll.dae" scale="0.1 0.1 0.1"/>
      </geometry>
    </visual>
    <collision>
      <geometry>
        <mesh filename="package://nao_meshes/meshes/V40/collision/LShoulderRoll.stl" scale="0.1 0.1 0.1"/>
      </geometry>
    </collision>
  </link>
  <joint name="LElbowYaw" type="revolute">
    <parent link="LBicep"/>
    <child link="LElbow"/>
    <origin rpy="0 0 0" xyz="0.105 0.015 0"/>
    <axis xyz="1.0 0 0"/>
    <limit effort="1.2" lower="-2.08567" upper="2.08567" velocity="8.26797"/>
  </joint>
  <link name="LElbow">
    <inertial>
      <mass value="0.05971"/>
      <inertia ixx="5.50319e-06" ixy="-2.243e-08" ixz="1.534e-08" iyy="6.2254e-05" iyz="5.59e-09" izz="6.32512e-05"/>
      <origin rpy="0 0 0" xyz="-0.0256 -1e-05 -0.00019"/>
    </inertial>
  </link>
  <joint name="LElbowRoll" type="revolute">
    <parent link="LElbow"/>
    <child link="LForeArm"/>
    <origin rpy="0 0 0" xyz="0 0 0"/>
    <axis xyz="0 0 1.0"/>
    <limit effort="1.2" lower="-1.54462" upper="-0.0349066" velocity="7.19407"/>
  </joint>
  <link name="LForeArm">
    <inertial>
      <mass value="0.07724"/>
      <inertia ixx="2.51948e-05" ixy="-2.16293e-06" ixz="-7.1846e-07" iyy="8.89032e-05" iyz="-1.0809e-07" izz="8.68687e-05"/>
      <origin rpy="0 0 0" xyz="0.02556 0.00273 0.00096"/>
    </inertial>
    <visual>
      <geometry>
        <mesh filename="package://nao_meshes/meshes/V40/visual/LElbowRoll.dae" scale="0.1 0.1 0.1"/>
      </geometry>
    </visual>
    <collision>
      <geometry>
        <mesh filename="package://nao_meshes/meshes/V40/collision/LElbowRoll.stl" scale="0.1 0.1 0.1"/>
      </geometry>
    </collision>
  </link>
  <joint name="LWristYaw" type="revolute">
    <parent link="LForeArm"/>
    <child link="l_wrist"/>
    <origin rpy="0 0 0" xyz="0.05595 0 0"/>
    <axis xyz="1.0 0 0"/>
    <limit effort="0.76" lower="-1.82387" upper="1.82387" velocity="24.6229"/>
  </joint>
  <link name="l_wrist">
    <inertial>
      <mass value="0.16653"/>
      <inertia ixx="6.10568e-05" ixy="-5.0364e-06" ixz="-3.89537e-05" iyy="0.000279474" iyz="-2.93076e-06" izz="0.000279988"/>
      <origin rpy="0 0 0" xyz="0.0318 0.00083 0.00477"/>
    </inertial>
    <visual>
      <geometry>
        <mesh filename="package://nao_meshes/meshes/V40/visual/LWristYaw.dae" scale="0.1 0.1 0.1"/>
      </geometry>
    </visual>
    <collision>
      <geometry>
        <mesh filename="package://nao_meshes/meshes/V40/collision/LWristYaw.stl" scale="0.1 0.1 0.1"/>
      </geometry>
    </collision>
  </link>
  <joint name="LHand" type="revolute">
    <parent link="l_wrist"/>
    <child link="l_gripper"/>
    <origin rpy="0 0 0" xyz="0.05775 0 -0.01231"/>
    <limit effort="0.177576" lower="0" upper="1.0" velocity="3"/>
  </joint>
  <link name="l_gripper">
    <inertial>
      <mass value="2e-06"/>
      <inertia ixx="1.1e-09" ixy="0" ixz="0" iyy="1.1e-09" iyz="0" izz="1.1e-09"/>
      <origin rpy="0 0 0" xyz="0 0 0"/>
    </inertial>
  </link>
  <joint name="RShoulderPitch" type="revolute">
    <parent link="torso"/>
    <child link="RShoulder"/>
    <origin rpy="0 0 0" xyz="0 -0.098 0.1"/>
    <axis xyz="0 1.0 0"/>
    <limit effort="1.2" lower="-2.08567" upper="2.08567" velocity="8.26797"/>
  </joint>
  <link name="RShoulder">
    <inertial>
      <mass value="0.06996"/>
      <inertia ixx="7.1025e-05" ixy="2.02467e-06" ixz="1.722e-08" iyy="1.4058e-05" iyz="-8.41e-09" izz="7.3166e-05"/>
      <origin rpy="0 0 0" xyz="-0.00178 0.02496 0.00018"/>
    </inertial>
    <visual>
      <geometry>
        <mesh filename="package://nao_meshes/meshes/V40/visual/RShoulderPitch.dae" scale="0.1 0.1 0.1"/>
      </geometry>
    </visual>
    <collision>
      <geometry>
        <mesh filename="package://nao_meshes/meshes/V40/collision/RShoulderPitch.stl" scale="0.1 0.1 0.1"/>
      </geometry>
    </collision>
  </link>
  <joint name="RShoulderRoll" type="revolute">
    <parent link="RShoulder"/>
    <child link="RBicep"/>
    <origin rpy="0 0 0" xyz="0 0 0"/>
    <axis xyz="0 0 1.0"/>
    <limit effort="1.2" lower="-1.32645" upper="0.314159" velocity="7.19407"/>
  </joint>
  <link name="RBicep">
    <inertial>
      <mass value="0.12309"/>
      <inertia ixx="8.22841e-05" ixy="3.97806e-05" ixz="-7.52601e-06" iyy="0.000290014" iyz="1.52945e-06" izz="0.000268423"/>
      <origin rpy="0 0 0" xyz="0.01885 -0.00577 0.00065"/>
    </inertial>
    <visual>
      <geometry>
        <mesh filename="package://nao_meshes/meshes/V40/visual/RShoulderRoll.dae" scale="0.1 0.1 0.1"/>
      </geometry>
    </visual>
    <collision>
      <geometry>
        <mesh filename="package://nao_meshes/meshes/V40/collision/RShoulderRoll.stl" scale="0.1 0.1 0.1"/>
      </geometry>
    </collision>
  </link>
  <joint name="RElbowYaw" type="revolute">
    <parent link="RBicep"/>
    <child link="RElbow"/>
    <origin rpy="0 0 0" xyz="0.105 -0.015 0"/>
    <axis xyz="1.0 0 0"/>
    <limit effort="1.2" lower="-2.08567" upper="2.08567" velocity="8.26797"/>
  </joint>
  <link name="RElbow">
    <inertial>
      <mass value="0.05971"/>
      <inertia ixx="5.50319e-06" ixy="2.243e-08" ixz="1.534e-08" iyy="6.2254e-05" iyz="-5.59e-09" izz="6.32512e-05"/>
      <origin rpy="0 0 0" xyz="-0.0256 1e-05 -0.00019"/>
    </inertial>
  </link>
  <joint name="RElbowRoll" type="revolute">
    <parent link="RElbow"/>
    <child link="RForeArm"/>
    <origin rpy="0 0 0" xyz="0 0 0"/>
    <axis xyz="0 0 1.0"/>
    <limit effort="1.2" lower="0.0349066" upper="1.54462" velocity="7.19407"/>
  </joint>
  <link name="RForeArm">
    <inertial>
      <mass value="0.07724"/>
      <inertia ixx="2.51948e-05" ixy="2.16293e-06" ixz="-7.1846e-07" iyy="8.89032e-05" iyz="1.0809e-07" izz="8.68687e-05"/>
      <origin rpy="0 0 0" xyz="0.02556 -0.00273 0.00096"/>
    </inertial>
    <visual>
      <geometry>
        <mesh filename="package://nao_meshes/meshes/V40/visual/RElbowRoll.dae" scale="0.1 0.1 0.1"/>
      </geometry>
    </visual>
    <collision>
      <geometry>
        <mesh filename="package://nao_meshes/meshes/V40/collision/RElbowRoll.stl" scale="0.1 0.1 0.1"/>
      </geometry>
    </collision>
  </link>
  <joint name="RWristYaw" type="revolute">
    <parent link="RForeArm"/>
    <child link="r_wrist"/>
    <origin rpy="0 0 0" xyz="0.05595 0 0"/>
    <axis xyz="1.0 0 0"/>
    <limit effort="0.76" lower="-1.82387" upper="1.82387" velocity="24.6229"/>
  </joint>
  <link name="r_wrist">
    <inertial>
      <mass value="0.16653"/>
      <inertia ixx="6.10568e-05" ixy="5.0364e-06" ixz="-3.89537e-05" iyy="0.000279474" iyz="2.93076e-06" izz="0.000279988"/>
      <origin rpy="0 0 0" xyz="0.0318 -0.00083 0.00477"/>
    </inertial>
    <visual>
      <geometry>
        <mesh filename="package://nao_meshes/meshes/V40/visual/RWristYaw.dae" scale="0.1 0.1 0.1"/>
      </geometry>
    </visual>
    <collision>
      <geometry>
        <mesh filename="package://nao_meshes/meshes/V40/collision/RWristYaw.stl" scale="0.1 0.1 0.1"/>
      </geometry>
    </collision>
  </link>
  <joint name="RHand" type="revolute">
    <parent link="r_wrist"/>
    <child link="r_gripper"/>
    <origin rpy="0 0 0" xyz="0.05775 0 -0.01231"/>
    <limit effort="0.177576" lower="0" upper="1.0" velocity="3"/>
  </joint>
  <link name="r_gripper">
    <inertial>
      <mass value="2e-06"/>
      <inertia ixx="1.1e-09" ixy="0" ixz="0" iyy="1.1e-09" iyz="0" izz="1.1e-09"/>
      <origin rpy="0 0 0" xyz="0 0 0"/>
    </inertial>
  </link>
  <link name="RHandTouchBack_frame"/>
  <joint name="RHandTouchBack_joint" type="fixed">
    <parent link="r_wrist"/>
    <child link="RHandTouchBack_frame"/>
    <origin rpy="0 -1.57079632679 0" xyz="0.038 0 0.025"/>
  </joint>
  <link name="RFsrFL_frame"/>
  <joint name="RFsrFL_joint" type="fixed">
    <parent link="r_ankle"/>
    <child link="RFsrFL_frame"/>
    <origin rpy="0 0 0" xyz="0.07025 0.0231 0"/>
  </joint>
  <link name="RFsrRL_frame"/>
  <joint name="RFsrRL_joint" type="fixed">
    <parent link="r_ankle"/>
    <child link="RFsrRL_frame"/>
    <origin rpy="0 0 0" xyz="-0.03025 0.0191 0"/>
  </joint>
  <link name="LSonar_frame"/>
  <joint name="LSonar_joint" type="fixed">
    <parent link="torso"/>
    <child link="LSonar_frame"/>
    <origin rpy="0 0.04365 0.39265" xyz="0.0507 0.03785 0.06035"/>
  </joint>
  <link name="LFsrFR_frame"/>
  <joint name="LFsrFR_joint" type="fixed">
    <parent link="l_ankle"/>
    <child link="LFsrFR_frame"/>
    <origin rpy="0 0 0" xyz="0.07025 -0.0231 0"/>
  </joint>
  <link name="HeadTouchRear_frame"/>
  <joint name="HeadTouchRear_joint" type="fixed">
    <parent link="Head"/>
    <child link="HeadTouchRear_frame"/>
    <origin rpy="3.14159265359 -1.333192995 3.14159265359" xyz="-0.0257 0 0.1045"/>
  </joint>
  <link name="ImuAccelerometer_frame"/>
  <joint name="ImuAccelerometer_joint" type="fixed">
    <parent link="torso"/>
    <child link="ImuAccelerometer_frame"/>
    <origin rpy="0 0 0" xyz="-0.008 0.00606 0.027"/>
  </joint>
  <link name="HeadTouchMiddle_frame"/>
  <joint name="HeadTouchMiddle_joint" type="fixed">
    <parent link="Head"/>
    <child link="HeadTouchMiddle_frame"/>
    <origin rpy="0 -1.57079632679 0" xyz="0.001 0 0.1099"/>
  </joint>
  <link name="ImuGyrometer_frame"/>
  <joint name="ImuGyrometer_joint" type="fixed">
    <parent link="torso"/>
    <child link="ImuGyrometer_frame"/>
    <origin rpy="0 0 0" xyz="-0.008 -0.006 0.029"/>
  </joint>
  <link name="LFsrRL_frame"/>
  <joint name="LFsrRL_joint" type="fixed">
    <parent link="l_ankle"/>
    <child link="LFsrRL_frame"/>
    <origin rpy="0 0 0" xyz="-0.03025 0.0299 0"/>
  </joint>
  <link name="RFootBumperRight_frame"/>
  <joint name="RFootBumperRight_joint" type="fixed">
    <parent link="r_ankle"/>
    <child link="RFootBumperRight_frame"/>
    <origin rpy="0 0 0" xyz="0.0876 -0.019 -0.035"/>
  </joint>
  <link name="LHandTouchLeft_frame"/>
  <joint name="LHandTouchLeft_joint" type="fixed">
    <parent link="l_wrist"/>
    <child link="LHandTouchLeft_frame"/>
    <origin rpy="0 0 0" xyz="0.032 0.025 0.003"/>
  </joint>
  <link name="RInfraRed_frame"/>
  <joint name="RInfraRed_joint" type="fixed">
    <parent link="Head"/>
    <child link="RInfraRed_frame"/>
    <origin rpy="0 0 0" xyz="0.0441 -0.0257 0.0466"/>
  </joint>
  <link name="LFootBumperLeft_frame"/>
  <joint name="LFootBumperLeft_joint" type="fixed">
    <parent link="l_ankle"/>
    <child link="LFootBumperLeft_frame"/>
    <origin rpy="0 0 0" xyz="0.0876 0.019 -0.035"/>
  </joint>
  <link name="ChestButton_frame"/>
  <joint name="ChestButton_joint" type="fixed">
    <parent link="torso"/>
    <child link="ChestButton_frame"/>
    <origin rpy="0 0 0" xyz="0.049871 0.001588 0.055163"/>
  </joint>
  <link name="RFootBumperLeft_frame"/>
  <joint name="RFootBumperLeft_joint" type="fixed">
    <parent link="r_ankle"/>
    <child link="RFootBumperLeft_frame"/>
    <origin rpy="0 0 0" xyz="0.0876 0.014 -0.035"/>
  </joint>
  <link name="LFsrRR_frame"/>
  <joint name="LFsrRR_joint" type="fixed">
    <parent link="l_ankle"/>
    <child link="LFsrRR_frame"/>
    <origin rpy="0 0 0" xyz="-0.02965 -0.0191 0"/>
  </joint>
  <link name="LFootBumperRight_frame"/>
  <joint name="LFootBumperRight_joint" type="fixed">
    <parent link="l_ankle"/>
    <child link="LFootBumperRight_frame"/>
    <origin rpy="0 0 0" xyz="0.0876 -0.014 -0.035"/>
  </joint>
  <link name="RFsrFR_frame"/>
  <joint name="RFsrFR_joint" type="fixed">
    <parent link="r_ankle"/>
    <child link="RFsrFR_frame"/>
    <origin rpy="0 0 0" xyz="0.07025 -0.0299 0"/>
  </joint>
  <link name="RHandTouchLeft_frame"/>
  <joint name="RHandTouchLeft_joint" type="fixed">
    <parent link="r_wrist"/>
    <child link="RHandTouchLeft_frame"/>
    <origin rpy="0 0 0" xyz="0.032 0.025 0.003"/>
  </joint>
  <link name="RFsrRR_frame"/>
  <joint name="RFsrRR_joint" type="fixed">
    <parent link="r_ankle"/>
    <child link="RFsrRR_frame"/>
    <origin rpy="0 0 0" xyz="-0.02965 -0.0299 0"/>
  </joint>
  <link name="LFsrFL_frame"/>
  <joint name="LFsrFL_joint" type="fixed">
    <parent link="l_ankle"/>
    <child link="LFsrFL_frame"/>
    <origin rpy="0 0 0" xyz="0.07025 0.0299 0"/>
  </joint>
  <link name="HeadTouchFront_frame"/>
  <joint name="HeadTouchFront_joint" type="fixed">
    <parent link="Head"/>
    <child link="HeadTouchFront_frame"/>
    <origin rpy="0 -1.186099535 0" xyz="0.0312 0 0.1014"/>
  </joint>
  <link name="CameraBottom_frame"/>
  <joint name="CameraBottom_joint" type="fixed">
    <parent link="Head"/>
    <child link="CameraBottom_frame"/>
    <origin rpy="0 0.6981 0" xyz="0.0488 0 0.02381"/>
  </joint>
  <link name="LHandTouchRight_frame"/>
  <joint name="LHandTouchRight_joint" type="fixed">
    <parent link="l_wrist"/>
    <child link="LHandTouchRight_frame"/>
    <origin rpy="0 0 0" xyz="0.035 -0.025 0.0035"/>
  </joint>
  <link name="RSonar_frame"/>
  <joint name="RSonar_joint" type="fixed">
    <parent link="torso"/>
    <child link="RSonar_frame"/>
    <origin rpy="0 0.04365 -0.39265" xyz="0.0507 -0.03785 0.06035"/>
  </joint>
  <link name="CameraTop_frame"/>
  <joint name="CameraTop_joint" type="fixed">
    <parent link="Head"/>
    <child link="CameraTop_frame"/>
    <origin rpy="0 0 0" xyz="0.0539 0 0.0679"/>
  </joint>
  <link name="LHandTouchBack_frame"/>
  <joint name="LHandTouchBack_joint" type="fixed">
    <parent link="l_wrist"/>
    <child link="LHandTouchBack_frame"/>
    <origin rpy="0 -1.57079632679 0" xyz="0.038 0 0.025"/>
  </joint>
  <link name="LInfraRed_frame"/>
  <joint name="LInfraRed_joint" type="fixed">
    <parent link="Head"/>
    <child link="LInfraRed_frame"/>
    <origin rpy="0 0 0" xyz="0.0441 0.0257 0.0466"/>
  </joint>
  <link name="RHandTouchRight_frame"/>
  <joint name="RHandTouchRight_joint" type="fixed">
    <parent link="r_wrist"/>
    <child link="RHandTouchRight_frame"/>
    <origin rpy="0 0 0" xyz="0.035 -0.025 0.0035"/>
  </joint>
</robot>

