<?xml version="1.0" ?>
<!-- ***************************************************************** 
 ****** File automatically generated by generate_urdf.py script ****** 
 ********************************************************************* -->
<robot xmlns:xacro="http://www.ros.org/wiki/xacro">
	<joint name="LShoulderPitch" type="revolute">
		<parent link="torso"/>
		<child link="LShoulder"/>
		<origin rpy="0 0 0" xyz="0 0.098 0.1"/>
		<axis xyz="0 1.0 0"/>
		<limit effort="1.2" lower="-2.08567" upper="2.08567" velocity="8.26797"/>
	</joint>
	<link name="LShoulder">
		<inertial>
			<mass value="0.06996"/>
			<inertia ixx="7.1025e-05" ixy="-2.02467e-06" ixz="1.722e-08" iyy="1.4058e-05" iyz="8.41e-09" izz="7.3166e-05"/>
			<origin rpy="0 0 0" xyz="-0.00178 -0.02496 0.00018"/>
		</inertial>
		<xacro:insert_visu_LShoulder/>
	</link>
	<joint name="LShoulderRoll" type="revolute">
		<parent link="LShoulder"/>
		<child link="LBicep"/>
		<origin rpy="0 0 0" xyz="0 0 0"/>
		<axis xyz="0 0 1.0"/>
		<limit effort="1.2" lower="-0.314159" upper="1.32645" velocity="7.19407"/>
	</joint>
	<link name="LBicep">
		<inertial>
			<mass value="0.12309"/>
			<inertia ixx="8.22841e-05" ixy="-3.97806e-05" ixz="-7.52601e-06" iyy="0.000290014" iyz="-1.52945e-06" izz="0.000268423"/>
			<origin rpy="0 0 0" xyz="0.01885 0.00577 0.00065"/>
		</inertial>
		<xacro:insert_visu_LBicep/>
	</link>
	<joint name="LElbowYaw" type="revolute">
		<parent link="LBicep"/>
		<child link="LElbow"/>
		<origin rpy="0 0 0" xyz="0.105 0.015 0"/>
		<axis xyz="1.0 0 0"/>
		<limit effort="1.2" lower="-2.08567" upper="2.08567" velocity="8.26797"/>
	</joint>
	<link name="LElbow">
		<inertial>
			<mass value="0.05971"/>
			<inertia ixx="5.50319e-06" ixy="-2.243e-08" ixz="1.534e-08" iyy="6.2254e-05" iyz="5.59e-09" izz="6.32512e-05"/>
			<origin rpy="0 0 0" xyz="-0.0256 -1e-05 -0.00019"/>
		</inertial>
	</link>
	<joint name="LElbowRoll" type="revolute">
		<parent link="LElbow"/>
		<child link="LForeArm"/>
		<origin rpy="0 0 0" xyz="0 0 0"/>
		<axis xyz="0 0 1.0"/>
		<limit effort="1.2" lower="-1.54462" upper="-0.0349066" velocity="7.19407"/>
	</joint>
	<link name="LForeArm">
		<inertial>
			<mass value="0.07724"/>
			<inertia ixx="2.51948e-05" ixy="-2.16293e-06" ixz="-7.1846e-07" iyy="8.89032e-05" iyz="-1.0809e-07" izz="8.68687e-05"/>
			<origin rpy="0 0 0" xyz="0.02556 0.00273 0.00096"/>
		</inertial>
		<xacro:insert_visu_LForeArm/>
	</link>
	<joint name="LWristYaw" type="revolute">
		<parent link="LForeArm"/>
		<child link="l_wrist"/>
		<origin rpy="0 0 0" xyz="0.05595 0 0"/>
		<axis xyz="1.0 0 0"/>
		<limit effort="0.76" lower="-1.82387" upper="1.82387" velocity="24.6229"/>
	</joint>
	<link name="l_wrist">
		<inertial>
			<mass value="0.16653"/>
			<inertia ixx="6.10568e-05" ixy="-5.0364e-06" ixz="-3.89537e-05" iyy="0.000279474" iyz="-2.93076e-06" izz="0.000279988"/>
			<origin rpy="0 0 0" xyz="0.0318 0.00083 0.00477"/>
		</inertial>
		<xacro:insert_visu_l_wrist/>
	</link>
	<joint name="LHand" type="revolute">
		<parent link="l_wrist"/>
		<child link="l_gripper"/>
		<origin rpy="0 0 0" xyz="0.05775 0 -0.01231"/>
		<limit effort="0.177576" lower="0" upper="1.0" velocity="3"/>
	</joint>
	<link name="l_gripper">
		<inertial>
			<mass value="2e-06"/>
			<inertia ixx="1.1e-09" ixy="0" ixz="0" iyy="1.1e-09" iyz="0" izz="1.1e-09"/>
			<origin rpy="0 0 0" xyz="0 0 0"/>
		</inertial>
	</link>
	<joint name="RShoulderPitch" type="revolute">
		<parent link="torso"/>
		<child link="RShoulder"/>
		<origin rpy="0 0 0" xyz="0 -0.098 0.1"/>
		<axis xyz="0 1.0 0"/>
		<limit effort="1.2" lower="-2.08567" upper="2.08567" velocity="8.26797"/>
	</joint>
	<link name="RShoulder">
		<inertial>
			<mass value="0.06996"/>
			<inertia ixx="7.1025e-05" ixy="2.02467e-06" ixz="1.722e-08" iyy="1.4058e-05" iyz="-8.41e-09" izz="7.3166e-05"/>
			<origin rpy="0 0 0" xyz="-0.00178 0.02496 0.00018"/>
		</inertial>
		<xacro:insert_visu_RShoulder/>
	</link>
	<joint name="RShoulderRoll" type="revolute">
		<parent link="RShoulder"/>
		<child link="RBicep"/>
		<origin rpy="0 0 0" xyz="0 0 0"/>
		<axis xyz="0 0 1.0"/>
		<limit effort="1.2" lower="-1.32645" upper="0.314159" velocity="7.19407"/>
	</joint>
	<link name="RBicep">
		<inertial>
			<mass value="0.12309"/>
			<inertia ixx="8.22841e-05" ixy="3.97806e-05" ixz="-7.52601e-06" iyy="0.000290014" iyz="1.52945e-06" izz="0.000268423"/>
			<origin rpy="0 0 0" xyz="0.01885 -0.00577 0.00065"/>
		</inertial>
		<xacro:insert_visu_RBicep/>
	</link>
	<joint name="RElbowYaw" type="revolute">
		<parent link="RBicep"/>
		<child link="RElbow"/>
		<origin rpy="0 0 0" xyz="0.105 -0.015 0"/>
		<axis xyz="1.0 0 0"/>
		<limit effort="1.2" lower="-2.08567" upper="2.08567" velocity="8.26797"/>
	</joint>
	<link name="RElbow">
		<inertial>
			<mass value="0.05971"/>
			<inertia ixx="5.50319e-06" ixy="2.243e-08" ixz="1.534e-08" iyy="6.2254e-05" iyz="-5.59e-09" izz="6.32512e-05"/>
			<origin rpy="0 0 0" xyz="-0.0256 1e-05 -0.00019"/>
		</inertial>
	</link>
	<joint name="RElbowRoll" type="revolute">
		<parent link="RElbow"/>
		<child link="RForeArm"/>
		<origin rpy="0 0 0" xyz="0 0 0"/>
		<axis xyz="0 0 1.0"/>
		<limit effort="1.2" lower="0.0349066" upper="1.54462" velocity="7.19407"/>
	</joint>
	<link name="RForeArm">
		<inertial>
			<mass value="0.07724"/>
			<inertia ixx="2.51948e-05" ixy="2.16293e-06" ixz="-7.1846e-07" iyy="8.89032e-05" iyz="1.0809e-07" izz="8.68687e-05"/>
			<origin rpy="0 0 0" xyz="0.02556 -0.00273 0.00096"/>
		</inertial>
		<xacro:insert_visu_RForeArm/>
	</link>
	<joint name="RWristYaw" type="revolute">
		<parent link="RForeArm"/>
		<child link="r_wrist"/>
		<origin rpy="0 0 0" xyz="0.05595 0 0"/>
		<axis xyz="1.0 0 0"/>
		<limit effort="0.76" lower="-1.82387" upper="1.82387" velocity="24.6229"/>
	</joint>
	<link name="r_wrist">
		<inertial>
			<mass value="0.16653"/>
			<inertia ixx="6.10568e-05" ixy="5.0364e-06" ixz="-3.89537e-05" iyy="0.000279474" iyz="2.93076e-06" izz="0.000279988"/>
			<origin rpy="0 0 0" xyz="0.0318 -0.00083 0.00477"/>
		</inertial>
		<xacro:insert_visu_r_wrist/>
	</link>
	<joint name="RHand" type="revolute">
		<parent link="r_wrist"/>
		<child link="r_gripper"/>
		<origin rpy="0 0 0" xyz="0.05775 0 -0.01231"/>
		<limit effort="0.177576" lower="0" upper="1.0" velocity="3"/>
	</joint>
	<link name="r_gripper">
		<inertial>
			<mass value="2e-06"/>
			<inertia ixx="1.1e-09" ixy="0" ixz="0" iyy="1.1e-09" iyz="0" izz="1.1e-09"/>
			<origin rpy="0 0 0" xyz="0 0 0"/>
		</inertial>
	</link>
</robot>
