<?xml version="1.0" ?>
<!-- ***************************************************************** 
 ****** File automatically generated by generate_urdf.py script ****** 
 ********************************************************************* -->
<robot xmlns:xacro="http://www.ros.org/wiki/xacro">
	<joint name="HeadYaw" type="revolute">
		<parent link="torso"/>
		<child link="Neck"/>
		<origin rpy="0 0 0" xyz="0 0 0.1265"/>
		<axis xyz="0 0 1.0"/>
		<limit effort="1.2" lower="-2.08567" upper="2.08567" velocity="8.26797"/>
	</joint>
	<link name="Neck">
		<inertial>
			<mass value="0.0593"/>
			<inertia ixx="6.18031e-05" ixy="-2.05e-09" ixz="-4.948e-08" iyy="6.28186e-05" iyz="-5.067e-08" izz="5.43977e-06"/>
			<origin rpy="0 0 0" xyz="-2e-05 0 -0.02556"/>
		</inertial>
		<xacro:insert_visu_Neck/>
	</link>
	<joint name="HeadPitch" type="revolute">
		<parent link="Neck"/>
		<child link="Head"/>
		<origin rpy="0 0 0" xyz="0 0 0"/>
		<axis xyz="0 1.0 0"/>
		<limit effort="1.2" lower="-0.671952" upper="0.514872" velocity="7.19407"/>
	</joint>
	<link name="Head">
		<inertial>
			<mass value="0.52065"/>
			<inertia ixx="0.00226587" ixy="7.87181e-06" ixz="-1.19265e-05" iyy="0.00226421" iyz="-2.31846e-06" izz="0.000873733"/>
			<origin rpy="0 0 0" xyz="0.0012 0 0.05353"/>
		</inertial>
		<xacro:insert_visu_Head/>
	</link>
	<joint name="gaze_joint" type="fixed">
		<parent link="Head"/>
		<child link="gaze"/>
		<origin rpy="0 0 0" xyz="0.0539 0 0.0679"/>
	</joint>
	<link name="gaze"/>
</robot>
