<?xml version="1.0" ?>
<!-- ***************************************************************** 
 ****** File automatically generated by generate_urdf.py script ****** 
 ********************************************************************* -->
<robot xmlns:xacro="http://www.ros.org/wiki/xacro">
	<joint name="LHipYawPitch" type="revolute">
		<parent link="torso"/>
		<child link="LPelvis"/>
		<origin rpy="0 0 0" xyz="0 0.05 -0.085"/>
		<axis xyz="0 0.707106 -0.707106"/>
		<limit effort="3.2" lower="-1.14529" upper="0.740718" velocity="4.16174"/>
	</joint>
	<link name="LPelvis">
		<inertial>
			<mass value="0.07117"/>
			<inertia ixx="8.99716e-05" ixy="-5.00214e-06" ixz="1.27355e-05" iyy="0.000105523" iyz="2.77007e-05" izz="6.68838e-05"/>
			<origin rpy="0 0 0" xyz="-0.00766 -0.012 0.02717"/>
		</inertial>
		<xacro:insert_visu_LPelvis/>
	</link>
	<joint name="LHipRoll" type="revolute">
		<parent link="LPelvis"/>
		<child link="LHip"/>
		<origin rpy="0 0 0" xyz="0 0 0"/>
		<axis xyz="1.0 0 0"/>
		<limit effort="3.2" lower="-0.379435" upper="0.79046" velocity="4.16174"/>
	</joint>
	<link name="LHip">
		<inertial>
			<mass value="0.1353"/>
			<inertia ixx="2.79131e-05" ixy="4.982e-08" ixz="-5.30968e-06" iyy="0.000101469" iyz="0" izz="0.000292094"/>
			<origin rpy="0 0 0" xyz="-0.01649 0.00029 -0.00475"/>
		</inertial>
		<xacro:insert_visu_LHip/>
	</link>
	<joint name="LHipPitch" type="revolute">
		<parent link="LHip"/>
		<child link="LThigh"/>
		<origin rpy="0 0 0" xyz="0 0 0"/>
		<axis xyz="0 1.0 0"/>
		<limit effort="3.2" lower="-1.53589" upper="0.48398" velocity="6.40239"/>
	</joint>
	<link name="LThigh">
		<inertial>
			<mass value="0.39798"/>
			<inertia ixx="0.00166559" ixy="4.3251e-07" ixz="8.25051e-05" iyy="0.001625" iyz="3.17428e-05" izz="0.000304929"/>
			<origin rpy="0 0 0" xyz="0.00131 0.00201 -0.05386"/>
		</inertial>
		<xacro:insert_visu_LThigh/>
	</link>
	<joint name="LKneePitch" type="revolute">
		<parent link="LThigh"/>
		<child link="LTibia"/>
		<origin rpy="0 0 0" xyz="0 0 -0.1"/>
		<axis xyz="0 1.0 0"/>
		<limit effort="3.2" lower="-0.0923279" upper="2.11255" velocity="6.40239"/>
	</joint>
	<link name="LTibia">
		<inertial>
			<mass value="0.29159"/>
			<inertia ixx="0.00115383" ixy="7.7529e-07" ixz="3.23128e-05" iyy="0.00110378" iyz="4.39673e-05" izz="0.00018861"/>
			<origin rpy="0 0 0" xyz="0.00422 0.00252 -0.04868"/>
		</inertial>
		<xacro:insert_visu_LTibia/>
	</link>
	<joint name="LAnklePitch" type="revolute">
		<parent link="LTibia"/>
		<child link="l_ankle"/>
		<origin rpy="0 0 0" xyz="0 0 -0.1029"/>
		<axis xyz="0 1.0 0"/>
		<limit effort="3.2" lower="-1.18944" upper="0.922581" velocity="6.40239"/>
	</joint>
	<link name="l_ankle">
		<inertial>
			<mass value="0.13892"/>
			<inertia ixx="3.88258e-05" ixy="-4.942e-08" ixz="2.21321e-06" iyy="7.21158e-05" iyz="6.74e-09" izz="5.35199e-05"/>
			<origin rpy="0 0 0" xyz="0.00142 0.00028 0.00638"/>
		</inertial>
		<xacro:insert_visu_l_ankle/>
	</link>
	<joint name="LAnkleRoll" type="revolute">
		<parent link="l_ankle"/>
		<child link="l_sole"/>
		<origin rpy="0 0 0" xyz="0 0 0"/>
		<axis xyz="1.0 0 0"/>
		<limit effort="3.2" lower="-0.397761" upper="0.768992" velocity="4.16174"/>
	</joint>
	<link name="l_sole">
		<inertial>
			<mass value="0.16175"/>
			<inertia ixx="0.000269612" ixy="-5.8769e-06" ixz="0.000139244" iyy="0.000643878" iyz="1.8871e-05" izz="0.000525192"/>
			<origin rpy="0 0 0" xyz="0.0254 0.00332 -0.03241"/>
		</inertial>
		<xacro:insert_visu_l_sole/>
	</link>
	<joint name="RHipYawPitch" type="revolute">
		<parent link="torso"/>
		<child link="RPelvis"/>
		<origin rpy="0 0 0" xyz="0 -0.05 -0.085"/>
		<axis xyz="0 0.707106 0.707106"/>
		<limit effort="3.2" lower="-1.14529" upper="0.740718" velocity="4.16174"/>
	</joint>
	<link name="RPelvis">
		<inertial>
			<mass value="0.07117"/>
			<inertia ixx="8.99716e-05" ixy="5.00214e-06" ixz="1.27355e-05" iyy="0.000105523" iyz="-2.77007e-05" izz="6.68838e-05"/>
			<origin rpy="0 0 0" xyz="-0.00766 0.012 0.02717"/>
		</inertial>
		<xacro:insert_visu_RPelvis/>
	</link>
	<joint name="RHipRoll" type="revolute">
		<parent link="RPelvis"/>
		<child link="RHip"/>
		<origin rpy="0 0 0" xyz="0 0 0"/>
		<axis xyz="1.0 0 0"/>
		<limit effort="3.2" lower="-0.79046" upper="0.379435" velocity="4.16174"/>
	</joint>
	<link name="RHip">
		<inertial>
			<mass value="0.1353"/>
			<inertia ixx="2.79131e-05" ixy="-4.982e-08" ixz="-5.30968e-06" iyy="0.000101469" iyz="0" izz="0.000292094"/>
			<origin rpy="0 0 0" xyz="-0.01649 -0.00029 -0.00475"/>
		</inertial>
		<xacro:insert_visu_RHip/>
	</link>
	<joint name="RHipPitch" type="revolute">
		<parent link="RHip"/>
		<child link="RThigh"/>
		<origin rpy="0 0 0" xyz="0 0 0"/>
		<axis xyz="0 1.0 0"/>
		<limit effort="3.2" lower="-1.53589" upper="0.48398" velocity="6.40239"/>
	</joint>
	<link name="RThigh">
		<inertial>
			<mass value="0.39798"/>
			<inertia ixx="0.00166559" ixy="-4.3251e-07" ixz="8.25051e-05" iyy="0.001625" iyz="-3.17428e-05" izz="0.000304929"/>
			<origin rpy="0 0 0" xyz="0.00131 -0.00201 -0.05386"/>
		</inertial>
		<xacro:insert_visu_RThigh/>
	</link>
	<joint name="RKneePitch" type="revolute">
		<parent link="RThigh"/>
		<child link="RTibia"/>
		<origin rpy="0 0 0" xyz="0 0 -0.1"/>
		<axis xyz="0 1.0 0"/>
		<limit effort="3.2" lower="-0.0923279" upper="2.11255" velocity="6.40239"/>
	</joint>
	<link name="RTibia">
		<inertial>
			<mass value="0.29159"/>
			<inertia ixx="0.00115383" ixy="-7.7529e-07" ixz="3.23128e-05" iyy="0.00110378" iyz="-4.39673e-05" izz="0.00018861"/>
			<origin rpy="0 0 0" xyz="0.00422 -0.00252 -0.04868"/>
		</inertial>
		<xacro:insert_visu_RTibia/>
	</link>
	<joint name="RAnklePitch" type="revolute">
		<parent link="RTibia"/>
		<child link="r_ankle"/>
		<origin rpy="0 0 0" xyz="0 0 -0.1029"/>
		<axis xyz="0 1.0 0"/>
		<limit effort="3.2" lower="-1.1863" upper="0.932006" velocity="6.40239"/>
	</joint>
	<link name="r_ankle">
		<inertial>
			<mass value="0.13892"/>
			<inertia ixx="3.88258e-05" ixy="4.942e-08" ixz="2.21321e-06" iyy="7.21158e-05" iyz="-6.74e-09" izz="5.35199e-05"/>
			<origin rpy="0 0 0" xyz="0.00142 -0.00028 0.00638"/>
		</inertial>
		<xacro:insert_visu_r_ankle/>
	</link>
	<joint name="RAnkleRoll" type="revolute">
		<parent link="r_ankle"/>
		<child link="r_sole"/>
		<origin rpy="0 0 0" xyz="0 0 0"/>
		<axis xyz="1.0 0 0"/>
		<limit effort="3.2" lower="-0.768992" upper="0.397935" velocity="4.16174"/>
	</joint>
	<link name="r_sole">
		<inertial>
			<mass value="0.16175"/>
			<inertia ixx="0.000269612" ixy="5.8769e-06" ixz="0.000139244" iyy="0.000643878" iyz="-1.8871e-05" izz="0.000525192"/>
			<origin rpy="0 0 0" xyz="0.0254 -0.00332 -0.03241"/>
		</inertial>
		<xacro:insert_visu_r_sole/>
	</link>
</robot>
