<?xml version="1.0"?>

<!-- This file has been created by hand based on the work of Konstantinos Chatzilygeroudis in his nao_dcm project https://github.com/costashatz/nao_dcm -->
<robot xmlns:xacro="http://www.ros.org/wiki/xacro">
  <xacro:macro name="xacro:insert_visu_Finger" params="side num1 num2">
    <xacro:if value="${meshes_installed}">
      <visual>
        <origin rpy="0 -0 0" xyz="0 0 0"/>
        <geometry>
          <mesh filename="package://nao_meshes/meshes/V40/visual/${side}Finger${num1}${num2}.dae" scale="0.1 0.1 0.1"/>
        </geometry>
      </visual>
      <collision>
        <origin rpy="0 -0 0" xyz="0 0 0"/>
        <geometry>
          <mesh filename="package://nao_meshes/meshes/V40/collision/${side}Finger${num1}${num2}.stl" scale="0.1 0.1 0.1"/>
        </geometry>
      </collision>
    </xacro:if>
    <xacro:unless value="${meshes_installed}">
	  <visual>
        <origin xyz="0.000718 0 0" rpy="${PI_2} 0 ${PI_2}"/>
        <geometry>
          <box size="0.01 0.01 0.01436"/>
        </geometry>
        <material name="Yellow"/>
      </visual>
      <collision>
        <origin xyz="0.000718 0 0" rpy="${PI_2} 0 ${PI_2}"/>
        <geometry>
          <box size="0.01 0.01 0.01436"/>
        </geometry>
      </collision>
      </xacro:unless>
    </xacro:macro>

  <xacro:macro name="xacro:insert_visu_Thumb" params="side num1">
    <xacro:if value="${meshes_installed}">
      <visual>
        <origin rpy="0 -0 0" xyz="0 0 0"/>
        <geometry>
          <mesh filename="package://nao_meshes/meshes/V40/visual/${side}Thumb${num1}.dae" scale="0.1 0.1 0.1"/>
        </geometry>
      </visual>
      <collision>
        <origin rpy="0 -0 0" xyz="0 0 0"/>
        <geometry>
          <mesh filename="package://nao_meshes/meshes/V40/collision/${side}Thumb${num1}.stl" scale="0.1 0.1 0.1"/>
        </geometry>
      </collision>
    </xacro:if>
    <xacro:unless value="${meshes_installed}">
	  <visual>
        <origin xyz="0.000718 0 0" rpy="${PI_2} 0 ${PI_2}"/>
        <geometry>
          <box size="0.01 0.01 0.01436"/>
        </geometry>
        <material name="Yellow"/>
      </visual>
      <collision>
        <origin xyz="0.000718 0 0" rpy="${PI_2} 0 ${PI_2}"/>
        <geometry>
          <box size="0.01 0.01 0.01436"/>
        </geometry>
      </collision>
      </xacro:unless>
    </xacro:macro>


  <joint name="LFinger1" type="revolute">
    <parent link="l_wrist"/>
    <child link="LFinger11"/>
    <origin rpy="0 0 0" xyz="0.06907 0.01157 -0.00304"/>
    <axis xyz="0 1 0"/>
    <mimic joint="LHand" multiplier="-0.785398163398" offset="0.785398163398"/>
    <limit effort="10.0" lower="0.0" upper="0.785398163398" velocity="3.0"/>
  </joint>
  <link name="LFinger11">
    <xacro:insert_visu_Finger side="L" num1="1" num2="1"/>
    <inertial>
      <mass value="0.2e-5"/>
      <origin xyz="0 0 0"/>
      <inertia ixx="1e-9" ixy="0" ixz="0" iyy="1e-9" iyz="0" izz="1e-9"/>
    </inertial>
  </link>
  <joint name="LFinger1_1" type="revolute">
    <parent link="LFinger11"/>
    <child link="LFinger12"/>
    <origin rpy="0 0 0" xyz="0.01436 0 0"/>
    <axis xyz="0 1 0"/>
    <mimic joint="LHand" multiplier="-0.785398163398" offset="0.785398163398"/>
    <limit effort="10.0" lower="0.0" upper="0.785398163398" velocity="3.0"/>
  </joint>
  <link name="LFinger12">
    <xacro:insert_visu_Finger side="L" num1="1" num2="2"/>
    <inertial>
      <mass value="0.2e-5"/>
      <origin xyz="0 0 0"/>
      <inertia ixx="1e-9" ixy="0" ixz="0" iyy="1e-9" iyz="0" izz="1e-9"/>
    </inertial>
  </link>
  <joint name="LFinger1_2" type="revolute">
    <parent link="LFinger12"/>
    <child link="LFinger13"/>
    <origin rpy="0 0 0" xyz="0.01436 0 0"/>
    <axis xyz="0 1 0"/>
    <mimic joint="LHand" multiplier="-0.785398163398" offset="0.785398163398"/>
    <limit effort="10.0" lower="0.0" upper="0.785398163398" velocity="3.0"/>
  </joint>
  <link name="LFinger13">
    <xacro:insert_visu_Finger side="L" num1="1" num2="3"/>
    <inertial>
      <mass value="0.2e-5"/>
      <origin xyz="0 0 0"/>
      <inertia ixx="1e-9" ixy="0" ixz="0" iyy="1e-9" iyz="0" izz="1e-9"/>
    </inertial>
  </link>
  <joint name="LFinger2" type="revolute">
    <parent link="l_wrist"/>
    <child link="LFinger21"/>
    <origin rpy="0 0 0" xyz="0.06907 -0.01157 -0.00304"/>
    <axis xyz="0 1 0"/>
    <mimic joint="LHand" multiplier="-0.785398163398" offset="0.785398163398"/>
    <limit effort="10.0" lower="0.0" upper="0.785398163398" velocity="3.0"/>
  </joint>
  <link name="LFinger21">
    <xacro:insert_visu_Finger side="L" num1="2" num2="1"/>
    <inertial>
      <mass value="0.2e-5"/>
      <origin xyz="0 0 0"/>
      <inertia ixx="1e-9" ixy="0" ixz="0" iyy="1e-9" iyz="0" izz="1e-9"/>
    </inertial>
  </link>
  <joint name="LFinger2_1" type="revolute">
    <parent link="LFinger21"/>
    <child link="LFinger22"/>
    <origin rpy="0 0 0" xyz="0.01436 0 0"/>
    <axis xyz="0 1 0"/>
    <mimic joint="LHand" multiplier="-0.785398163398" offset="0.785398163398"/>
    <limit effort="10.0" lower="0.0" upper="0.785398163398" velocity="3.0"/>
  </joint>
  <link name="LFinger22">
    <xacro:insert_visu_Finger side="L" num1="2" num2="2"/>
    <inertial>
      <mass value="0.2e-5"/>
      <origin xyz="0 0 0"/>
      <inertia ixx="1e-9" ixy="0" ixz="0" iyy="1e-9" iyz="0" izz="1e-9"/>
    </inertial>
  </link>
  <joint name="LFinger2_2" type="revolute">
    <parent link="LFinger22"/>
    <child link="LFinger23"/>
    <origin rpy="0 0 0" xyz="0.01436 0 0"/>
    <axis xyz="0 1 0"/>
    <mimic joint="LHand" multiplier="-0.785398163398" offset="0.785398163398"/>
    <limit effort="10.0" lower="0.0" upper="0.785398163398" velocity="3.0"/>
  </joint>
  <link name="LFinger23">
    <xacro:insert_visu_Finger side="L" num1="2" num2="3"/>
    <inertial>
      <mass value="0.2e-5"/>
      <origin xyz="0 0 0"/>
      <inertia ixx="1e-9" ixy="0" ixz="0" iyy="1e-9" iyz="0" izz="1e-9"/>
    </inertial>
  </link> 


  <joint name="RFinger1" type="revolute">
    <parent link="r_wrist"/>
    <child link="RFinger11"/>
    <origin rpy="0 0 0" xyz="0.06907 0.01157 -0.00304"/>
    <axis xyz="0 1 0"/>
    <mimic joint="RHand" multiplier="-0.785398163398" offset="0.785398163398"/>
    <limit effort="10.0" lower="0.0" upper="0.785398163398" velocity="3.0"/>
  </joint>
  <link name="RFinger11">
    <xacro:insert_visu_Finger side="R" num1="1" num2="1"/>
    <inertial>
      <mass value="0.2e-5"/>
      <origin xyz="0 0 0"/>
      <inertia ixx="1e-9" ixy="0" ixz="0" iyy="1e-9" iyz="0" izz="1e-9"/>
    </inertial>
  </link>
  <joint name="RFinger1_1" type="revolute">
    <parent link="RFinger11"/>
    <child link="RFinger12"/>
    <origin rpy="0 0 0" xyz="0.01436 0 0"/>
    <axis xyz="0 1 0"/>
    <mimic joint="RHand" multiplier="-0.785398163398" offset="0.785398163398"/>
    <limit effort="10.0" lower="0.0" upper="0.785398163398" velocity="3.0"/>
  </joint>
  <link name="RFinger12">
    <xacro:insert_visu_Finger side="R" num1="1" num2="2"/>
    <inertial>
      <mass value="0.2e-5"/>
      <origin xyz="0 0 0"/>
      <inertia ixx="1e-9" ixy="0" ixz="0" iyy="1e-9" iyz="0" izz="1e-9"/>
    </inertial>
  </link>
  <joint name="RFinger1_2" type="revolute">
    <parent link="RFinger12"/>
    <child link="RFinger13"/>
    <origin rpy="0 0 0" xyz="0.01436 0 0"/>
    <axis xyz="0 1 0"/>
    <mimic joint="RHand" multiplier="-0.785398163398" offset="0.785398163398"/>
    <limit effort="10.0" lower="0.0" upper="0.785398163398" velocity="3.0"/>
  </joint>
  <link name="RFinger13">
    <xacro:insert_visu_Finger side="R" num1="1" num2="3"/>
    <inertial>
      <mass value="0.2e-5"/>
      <origin xyz="0 0 0"/>
      <inertia ixx="1e-9" ixy="0" ixz="0" iyy="1e-9" iyz="0" izz="1e-9"/>
    </inertial>
  </link>
  <joint name="RFinger2" type="revolute">
    <parent link="r_wrist"/>
    <child link="RFinger21"/>
    <origin rpy="0 0 0" xyz="0.06907 -0.01157 -0.00304"/>
    <axis xyz="0 1 0"/>
    <mimic joint="RHand" multiplier="-0.785398163398" offset="0.785398163398"/>
    <limit effort="10.0" lower="0.0" upper="0.785398163398" velocity="3.0"/>
  </joint>
  <link name="RFinger21">
    <xacro:insert_visu_Finger side="R" num1="2" num2="1"/>

    <inertial>
      <mass value="0.2e-5"/>
      <origin xyz="0 0 0"/>
      <inertia ixx="1e-9" ixy="0" ixz="0" iyy="1e-9" iyz="0" izz="1e-9"/>
    </inertial>
  </link>
  <joint name="RFinger2_1" type="revolute">
    <parent link="RFinger21"/>
    <child link="RFinger22"/>
    <origin rpy="0 0 0" xyz="0.01436 0 0"/>
    <axis xyz="0 1 0"/>
    <mimic joint="RHand" multiplier="-0.785398163398" offset="0.785398163398"/>
    <limit effort="10.0" lower="0.0" upper="0.785398163398" velocity="3.0"/>
  </joint>
  <link name="RFinger22">
    <xacro:insert_visu_Finger side="R" num1="2" num2="2"/>
    <inertial>
      <mass value="0.2e-5"/>
      <origin xyz="0 0 0"/>
      <inertia ixx="1e-9" ixy="0" ixz="0" iyy="1e-9" iyz="0" izz="1e-9"/>
    </inertial>
  </link>
  <joint name="RFinger2_2" type="revolute">
    <parent link="RFinger22"/>
    <child link="RFinger23"/>
    <origin rpy="0 0 0" xyz="0.01436 0 0"/>
    <axis xyz="0 1 0"/>
    <mimic joint="RHand" multiplier="-0.785398163398" offset="0.785398163398"/>
    <limit effort="10.0" lower="0.0" upper="0.785398163398" velocity="3.0"/>
  </joint>
  <link name="RFinger23">
    <xacro:insert_visu_Finger side="R" num1="2" num2="3"/>
    <inertial>
      <mass value="0.2e-5"/>
      <origin xyz="0 0 0"/>
      <inertia ixx="1e-9" ixy="0" ixz="0" iyy="1e-9" iyz="0" izz="1e-9"/>
    </inertial>
  </link>
  <joint name="LThumb1_joint" type="revolute">
    <parent link="l_wrist"/>
    <child link="LThumb1"/>
    <origin rpy="3.14159265359 0.785398163398 0" xyz="0.04895 0 -0.02638"/>
    <axis xyz="0 1 0"/>
    <mimic joint="LHand" multiplier="-0.785398163398" offset="0.785398163398"/>
    <limit effort="10.0" lower="0.0" upper="0.785398163398" velocity="3.0"/>
  </joint>
  <link name="LThumb1">
    <xacro:insert_visu_Thumb side="L" num1="1"/>
    <inertial>
      <mass value="0.2e-5"/>
      <origin xyz="0 0 0"/>
      <inertia ixx="1e-9" ixy="0" ixz="0" iyy="1e-9" iyz="0" izz="1e-9"/>
    </inertial>
  </link>
  <joint name="LThumb1_2" type="revolute">
    <parent link="LThumb1"/>
    <child link="LThumb2"/>
    <origin rpy="0 0 0" xyz="0.01436 0 0"/>
    <axis xyz="0 1 0"/>
    <mimic joint="LHand" multiplier="-0.785398163398" offset="0.785398163398"/>
    <limit effort="10.0" lower="0.0" upper="0.785398163398" velocity="3.0"/>
  </joint>
  <link name="LThumb2">
    <xacro:insert_visu_Thumb side="L" num1="2"/>
    <inertial>
      <mass value="0.2e-5"/>
      <origin xyz="0 0 0"/>
      <inertia ixx="1e-9" ixy="0" ixz="0" iyy="1e-9" iyz="0" izz="1e-9"/>
    </inertial>
  </link>
  <joint name="RThumb1_joint" type="revolute">
    <parent link="r_wrist"/>
    <child link="RThumb1"/>
    <origin rpy="3.14159265359 0.785398163398 0" xyz="0.04895 0 -0.02638"/>
    <axis xyz="0 1 0"/>
    <mimic joint="RHand" multiplier="-0.785398163398" offset="0.785398163398"/>
    <limit effort="10.0" lower="0.0" upper="0.785398163398" velocity="3.0"/>
  </joint>
  <link name="RThumb1">
    <xacro:insert_visu_Thumb side="R" num1="1"/>
    <inertial>
      <mass value="0.2e-5"/>
      <origin xyz="0 0 0"/>
      <inertia ixx="1e-9" ixy="0" ixz="0" iyy="1e-9" iyz="0" izz="1e-9"/>
    </inertial>
  </link>
  <joint name="RThumb1_2" type="revolute">
    <parent link="RThumb1"/>
    <child link="RThumb2"/>
    <origin rpy="0 0 0" xyz="0.01436 0 0"/>
    <axis xyz="0 1 0"/>
    <mimic joint="RHand" multiplier="-0.785398163398" offset="0.785398163398"/>
    <limit effort="10.0" lower="0.0" upper="0.785398163398" velocity="3.0"/>
  </joint>
  <link name="RThumb2">
    <xacro:insert_visu_Thumb side="R" num1="2"/>
    <inertial>
      <mass value="0.2e-5"/>
      <origin xyz="0 0 0"/>
      <inertia ixx="1e-9" ixy="0" ixz="0" iyy="1e-9" iyz="0" izz="1e-9"/>
    </inertial>
  </link> 
</robot>
