<?xml version="1.0" ?>
<!-- ***************************************************************** 
 ****** File automatically generated by generate_urdf.py script ****** 
 ********************************************************************* -->
<robot xmlns:xacro="http://www.ros.org/wiki/xacro">
	<joint name="HeadYaw" type="revolute">
		<parent link="torso"/>
		<child link="Neck"/>
		<origin rpy="0 0 0" xyz="0 0 0.1265"/>
		<axis xyz="0 0 1.0"/>
		<limit effort="1.2" lower="-2.08567" upper="2.08567" velocity="8.26797"/>
	</joint>
	<link name="Neck">
		<inertial>
			<mass value="0.06442"/>
			<inertia ixx="7.4993e-05" ixy="1.57e-09" ixz="-1.834e-08" iyy="7.6e-05" iyz="-5.295e-08" izz="5.53373e-06"/>
			<origin rpy="0 0 0" xyz="-1e-05 0 -0.02742"/>
		</inertial>
		<xacro:insert_visu_Neck/>
	</link>
	<joint name="HeadPitch" type="revolute">
		<parent link="Neck"/>
		<child link="Head"/>
		<origin rpy="0 0 0" xyz="0 0 0"/>
		<axis xyz="0 1.0 0"/>
		<limit effort="1.2" lower="-0.671952" upper="0.514872" velocity="7.19407"/>
	</joint>
	<link name="Head">
		<inertial>
			<mass value="0.60533"/>
			<inertia ixx="0.0026313" ixy="8.78814e-06" ixz="4.09847e-05" iyy="0.00249112" iyz="-2.99579e-05" izz="0.000985736"/>
			<origin rpy="0 0 0" xyz="-0.00112 0 0.05258"/>
		</inertial>
		<xacro:insert_visu_Head/>
	</link>
	<joint name="gaze_joint" type="fixed">
		<parent link="Head"/>
		<child link="gaze"/>
		<origin rpy="0 0.0209 0" xyz="0.05871 0 0.06364"/>
	</joint>
	<link name="gaze"/>
</robot>
