<?xml version="1.0" ?>
<!-- ***************************************************************** 
 ****** File automatically generated by generate_urdf.py script ****** 
 ********************************************************************* -->
<robot xmlns:xacro="http://www.ros.org/wiki/xacro">
	<joint name="LHipYawPitch" type="revolute">
		<parent link="torso"/>
		<child link="LPelvis"/>
		<origin rpy="0 0 0" xyz="0 0.05 -0.085"/>
		<axis xyz="0 0.707106 -0.707106"/>
		<limit effort="3.2" lower="-1.14529" upper="0.740718" velocity="4.16174"/>
	</joint>
	<link name="LPelvis">
		<inertial>
			<mass value="0.06981"/>
			<inertia ixx="8.15023e-05" ixy="-4.99449e-06" ixz="1.27482e-05" iyy="0.000101326" iyz="2.34547e-05" izz="6.26236e-05"/>
			<origin rpy="0 0 0" xyz="-0.00781 -0.01114 0.02661"/>
		</inertial>
		<xacro:insert_visu_LPelvis/>
	</link>
	<joint name="LHipRoll" type="revolute">
		<parent link="LPelvis"/>
		<child link="LHip"/>
		<origin rpy="0 0 0" xyz="0 0 0"/>
		<axis xyz="1.0 0 0"/>
		<limit effort="3.2" lower="-0.379435" upper="0.79046" velocity="4.16174"/>
	</joint>
	<link name="LHip">
		<inertial>
			<mass value="0.13053"/>
			<inertia ixx="2.75835e-05" ixy="-2.233e-08" ixz="-4.08164e-06" iyy="9.82706e-05" iyz="-4.19e-09" izz="8.80997e-05"/>
			<origin rpy="0 0 0" xyz="-0.01549 0.00029 -0.00515"/>
		</inertial>
		<xacro:insert_visu_LHip/>
	</link>
	<joint name="LHipPitch" type="revolute">
		<parent link="LHip"/>
		<child link="LThigh"/>
		<origin rpy="0 0 0" xyz="0 0 0"/>
		<axis xyz="0 1.0 0"/>
		<limit effort="3.2" lower="-1.53589" upper="0.48398" velocity="6.40239"/>
	</joint>
	<link name="LThigh">
		<inertial>
			<mass value="0.38968"/>
			<inertia ixx="0.00163672" ixy="9.2451e-07" ixz="8.53067e-05" iyy="0.00159107" iyz="3.83616e-05" izz="0.000303743"/>
			<origin rpy="0 0 0" xyz="0.00138 0.00221 -0.05373"/>
		</inertial>
		<xacro:insert_visu_LThigh/>
	</link>
	<joint name="LKneePitch" type="revolute">
		<parent link="LThigh"/>
		<child link="LTibia"/>
		<origin rpy="0 0 0" xyz="0 0 -0.1"/>
		<axis xyz="0 1.0 0"/>
		<limit effort="3.2" lower="-0.0923279" upper="2.11255" velocity="6.40239"/>
	</joint>
	<link name="LTibia">
		<inertial>
			<mass value="0.29142"/>
			<inertia ixx="0.00118208" ixy="6.3362e-07" ixz="3.6497e-05" iyy="0.00112865" iyz="3.94952e-05" izz="0.000193227"/>
			<origin rpy="0 0 0" xyz="0.00453 0.00225 -0.04936"/>
		</inertial>
		<xacro:insert_visu_LTibia/>
	</link>
	<joint name="LAnklePitch" type="revolute">
		<parent link="LTibia"/>
		<child link="l_ankle"/>
		<origin rpy="0 0 0" xyz="0 0 -0.1029"/>
		<axis xyz="0 1.0 0"/>
		<limit effort="3.2" lower="-1.18944" upper="0.922581" velocity="6.40239"/>
	</joint>
	<link name="l_ankle">
		<inertial>
			<mass value="0.13416"/>
			<inertia ixx="3.85098e-05" ixy="-2.634e-08" ixz="3.86194e-06" iyy="7.42653e-05" iyz="1.834e-08" izz="5.48654e-05"/>
			<origin rpy="0 0 0" xyz="0.00045 0.00029 0.00685"/>
		</inertial>
		<xacro:insert_visu_l_ankle/>
	</link>
	<joint name="LAnkleRoll" type="revolute">
		<parent link="l_ankle"/>
		<child link="l_sole"/>
		<origin rpy="0 0 0" xyz="0 0 0"/>
		<axis xyz="1.0 0 0"/>
		<limit effort="3.2" lower="-0.397761" upper="0.768992" velocity="4.16174"/>
	</joint>
	<link name="l_sole">
		<inertial>
			<mass value="0.16184"/>
			<inertia ixx="0.000269442" ixy="-5.69572e-06" ixz="0.000139379" iyy="0.000644343" iyz="1.87409e-05" izz="0.000525757"/>
			<origin rpy="0 0 0" xyz="0.02542 0.0033 -0.03239"/>
		</inertial>
		<xacro:insert_visu_l_sole/>
	</link>
	<joint name="RHipYawPitch" type="revolute">
		<parent link="torso"/>
		<child link="RPelvis"/>
		<origin rpy="0 0 0" xyz="0 -0.05 -0.085"/>
		<axis xyz="0 0.707106 0.707106"/>
		<limit effort="3.2" lower="-1.14529" upper="0.740718" velocity="4.16174"/>
	</joint>
	<link name="RPelvis">
		<inertial>
			<mass value="0.06981"/>
			<inertia ixx="8.9972e-05" ixy="5.00219e-06" ixz="1.27352e-05" iyy="0.000105526" iyz="-2.77008e-05" izz="6.68872e-05"/>
			<origin rpy="0 0 0" xyz="-0.00781 0.01114 0.02661"/>
		</inertial>
		<xacro:insert_visu_RPelvis/>
	</link>
	<joint name="RHipRoll" type="revolute">
		<parent link="RPelvis"/>
		<child link="RHip"/>
		<origin rpy="0 0 0" xyz="0 0 0"/>
		<axis xyz="1.0 0 0"/>
		<limit effort="3.2" lower="-0.79046" upper="0.379435" velocity="4.16174"/>
	</joint>
	<link name="RHip">
		<inertial>
			<mass value="0.13053"/>
			<inertia ixx="2.75865e-05" ixy="-1.919e-08" ixz="-4.10822e-06" iyy="9.827e-05" iyz="2.51e-09" izz="8.81033e-05"/>
			<origin rpy="0 0 0" xyz="-0.01549 -0.00029 -0.00515"/>
		</inertial>
		<xacro:insert_visu_RHip/>
	</link>
	<joint name="RHipPitch" type="revolute">
		<parent link="RHip"/>
		<child link="RThigh"/>
		<origin rpy="0 0 0" xyz="0 0 0"/>
		<axis xyz="0 1.0 0"/>
		<limit effort="3.2" lower="-1.53589" upper="0.48398" velocity="6.40239"/>
	</joint>
	<link name="RThigh">
		<inertial>
			<mass value="0.38968"/>
			<inertia ixx="0.00163748" ixy="-8.3954e-07" ixz="8.5883e-05" iyy="0.00159221" iyz="-3.91763e-05" izz="0.000303978"/>
			<origin rpy="0 0 0" xyz="0.00138 -0.00221 -0.05373"/>
		</inertial>
		<xacro:insert_visu_RThigh/>
	</link>
	<joint name="RKneePitch" type="revolute">
		<parent link="RThigh"/>
		<child link="RTibia"/>
		<origin rpy="0 0 0" xyz="0 0 -0.1"/>
		<axis xyz="0 1.0 0"/>
		<limit effort="3.2" lower="-0.0923279" upper="2.11255" velocity="6.40239"/>
	</joint>
	<link name="RTibia">
		<inertial>
			<mass value="0.29142"/>
			<inertia ixx="0.00118283" ixy="-8.965e-07" ixz="2.79969e-05" iyy="0.00112828" iyz="-3.8476e-05" izz="0.000191453"/>
			<origin rpy="0 0 0" xyz="0.00453 -0.00225 -0.04936"/>
		</inertial>
		<xacro:insert_visu_RTibia/>
	</link>
	<joint name="RAnklePitch" type="revolute">
		<parent link="RTibia"/>
		<child link="r_ankle"/>
		<origin rpy="0 0 0" xyz="0 0 -0.1029"/>
		<axis xyz="0 1.0 0"/>
		<limit effort="3.2" lower="-1.1863" upper="0.932006" velocity="6.40239"/>
	</joint>
	<link name="r_ankle">
		<inertial>
			<mass value="0.13416"/>
			<inertia ixx="3.85081e-05" ixy="6.434e-08" ixz="3.87466e-06" iyy="7.43108e-05" iyz="-4.58e-09" izz="5.49131e-05"/>
			<origin rpy="0 0 0" xyz="0.00045 -0.00029 0.00685"/>
		</inertial>
		<xacro:insert_visu_r_ankle/>
	</link>
	<joint name="RAnkleRoll" type="revolute">
		<parent link="r_ankle"/>
		<child link="r_sole"/>
		<origin rpy="0 0 0" xyz="0 0 0"/>
		<axis xyz="1.0 0 0"/>
		<limit effort="3.2" lower="-0.768992" upper="0.397935" velocity="4.16174"/>
	</joint>
	<link name="r_sole">
		<inertial>
			<mass value="0.16184"/>
			<inertia ixx="0.000269302" ixy="5.87505e-06" ixz="0.000139133" iyy="0.000643474" iyz="-1.88492e-05" izz="0.000525035"/>
			<origin rpy="0 0 0" xyz="0.02542 -0.0033 -0.03239"/>
		</inertial>
		<xacro:insert_visu_r_sole/>
	</link>
</robot>
