<?xml version="1.0" ?>
<!-- ***************************************************************** 
 ****** File automatically generated by generate_urdf.py script ****** 
 ********************************************************************* -->
<robot xmlns:xacro="http://www.ros.org/wiki/xacro">
	<joint name="LShoulderPitch" type="revolute">
		<parent link="torso"/>
		<child link="LShoulder"/>
		<origin rpy="0 0 0" xyz="0 0.098 0.1"/>
		<axis xyz="0 1.0 0"/>
		<limit effort="1.2" lower="-2.08567" upper="2.08567" velocity="8.26797"/>
	</joint>
	<link name="LShoulder">
		<inertial>
			<mass value="0.09304"/>
			<inertia ixx="8.42843e-05" ixy="-2.02802e-06" ixz="2.338e-08" iyy="1.41556e-05" iyz="-1.972e-08" izz="8.64195e-05"/>
			<origin rpy="0 0 0" xyz="-0.00165 -0.02663 0.00014"/>
		</inertial>
		<xacro:insert_visu_LShoulder/>
	</link>
	<joint name="LShoulderRoll" type="revolute">
		<parent link="LShoulder"/>
		<child link="LBicep"/>
		<origin rpy="0 0 0" xyz="0 0 0"/>
		<axis xyz="0 0 1.0"/>
		<limit effort="1.2" lower="-0.314159" upper="1.32645" velocity="7.19407"/>
	</joint>
	<link name="LBicep">
		<inertial>
			<mass value="0.15777"/>
			<inertia ixx="9.38999e-05" ixy="-4.71445e-05" ixz="-2.69947e-05" iyy="0.000371519" iyz="-2.45977e-06" izz="0.000341901"/>
			<origin rpy="0 0 0" xyz="0.02455 0.00563 0.0033"/>
		</inertial>
		<xacro:insert_visu_LBicep/>
	</link>
	<joint name="LElbowYaw" type="revolute">
		<parent link="LBicep"/>
		<child link="LElbow"/>
		<origin rpy="0 0 0" xyz="0.105 0.015 0"/>
		<axis xyz="1.0 0 0"/>
		<limit effort="1.2" lower="-2.08567" upper="2.08567" velocity="8.26797"/>
	</joint>
	<link name="LElbow">
		<inertial>
			<mass value="0.06483"/>
			<inertia ixx="5.59715e-06" ixy="4.21e-09" ixz="4.319e-08" iyy="7.54331e-05" iyz="-1.84e-09" izz="7.64434e-05"/>
			<origin rpy="0 0 0" xyz="-0.02744 0 -0.00014"/>
		</inertial>
	</link>
	<joint name="LElbowRoll" type="revolute">
		<parent link="LElbow"/>
		<child link="LForeArm"/>
		<origin rpy="0 0 0" xyz="0 0 0"/>
		<axis xyz="0 0 1.0"/>
		<limit effort="1.2" lower="-1.54462" upper="-0.0349066" velocity="7.19407"/>
	</joint>
	<link name="LForeArm">
		<inertial>
			<mass value="0.07761"/>
			<inertia ixx="2.53322e-05" ixy="-2.34271e-06" ixz="7.459e-08" iyy="8.91322e-05" iyz="-2.655e-08" izz="8.72873e-05"/>
			<origin rpy="0 0 0" xyz="0.02556 0.00281 0.00076"/>
		</inertial>
		<xacro:insert_visu_LForeArm/>
	</link>
	<joint name="LWristYaw" type="revolute">
		<parent link="LForeArm"/>
		<child link="l_wrist"/>
		<origin rpy="0 0 0" xyz="0.05595 0 0"/>
		<axis xyz="1.0 0 0"/>
		<limit effort="0.76" lower="-1.82387" upper="1.82387" velocity="24.6229"/>
	</joint>
	<link name="l_wrist">
		<inertial>
			<mass value="0.18533"/>
			<inertia ixx="7.05493e-05" ixy="5.71599e-06" ixz="-2.24744e-05" iyy="0.000356062" iyz="3.17771e-06" izz="0.000351919"/>
			<origin rpy="0 0 0" xyz="0.03434 -0.00088 0.00308"/>
		</inertial>
		<xacro:insert_visu_l_wrist/>
	</link>
	<joint name="LHand" type="revolute">
		<parent link="l_wrist"/>
		<child link="l_gripper"/>
		<origin rpy="0 0 0" xyz="0.05775 0 -0.01231"/>
		<limit effort="0.177576" lower="0" upper="1.0" velocity="3"/>
	</joint>
	<link name="l_gripper">
		<inertial>
			<mass value="2e-06"/>
			<inertia ixx="1.1e-09" ixy="0" ixz="0" iyy="1.1e-09" iyz="0" izz="1.1e-09"/>
			<origin rpy="0 0 0" xyz="0 0 0"/>
		</inertial>
	</link>
	<joint name="RShoulderPitch" type="revolute">
		<parent link="torso"/>
		<child link="RShoulder"/>
		<origin rpy="0 0 0" xyz="0 -0.098 0.1"/>
		<axis xyz="0 1.0 0"/>
		<limit effort="1.2" lower="-2.08567" upper="2.08567" velocity="8.26797"/>
	</joint>
	<link name="RShoulder">
		<inertial>
			<mass value="0.09304"/>
			<inertia ixx="8.42843e-05" ixy="2.02802e-06" ixz="2.338e-08" iyy="1.41556e-05" iyz="1.972e-08" izz="8.64195e-05"/>
			<origin rpy="0 0 0" xyz="-0.00165 0.02663 0.00014"/>
		</inertial>
		<xacro:insert_visu_RShoulder/>
	</link>
	<joint name="RShoulderRoll" type="revolute">
		<parent link="RShoulder"/>
		<child link="RBicep"/>
		<origin rpy="0 0 0" xyz="0 0 0"/>
		<axis xyz="0 0 1.0"/>
		<limit effort="1.2" lower="-1.32645" upper="0.314159" velocity="7.19407"/>
	</joint>
	<link name="RBicep">
		<inertial>
			<mass value="0.15777"/>
			<inertia ixx="0.00011012" ixy="7.66913e-05" ixz="-2.60461e-05" iyy="0.000367577" iyz="1.20983e-05" izz="0.000354618"/>
			<origin rpy="0 0 0" xyz="0.02455 -0.00563 0.0033"/>
		</inertial>
		<xacro:insert_visu_RBicep/>
	</link>
	<joint name="RElbowYaw" type="revolute">
		<parent link="RBicep"/>
		<child link="RElbow"/>
		<origin rpy="0 0 0" xyz="0.105 -0.015 0"/>
		<axis xyz="1.0 0 0"/>
		<limit effort="1.2" lower="-2.08567" upper="2.08567" velocity="8.26797"/>
	</joint>
	<link name="RElbow">
		<inertial>
			<mass value="0.06483"/>
			<inertia ixx="5.59715e-06" ixy="4.21e-09" ixz="4.319e-08" iyy="7.54331e-05" iyz="-1.84e-09" izz="7.64434e-05"/>
			<origin rpy="0 0 0" xyz="-0.02744 0 -0.00014"/>
		</inertial>
	</link>
	<joint name="RElbowRoll" type="revolute">
		<parent link="RElbow"/>
		<child link="RForeArm"/>
		<origin rpy="0 0 0" xyz="0 0 0"/>
		<axis xyz="0 0 1.0"/>
		<limit effort="1.2" lower="0.0349066" upper="1.54462" velocity="7.19407"/>
	</joint>
	<link name="RForeArm">
		<inertial>
			<mass value="0.07761"/>
			<inertia ixx="2.53907e-05" ixy="2.33243e-06" ixz="-6.0117e-07" iyy="8.92204e-05" iyz="2.694e-08" izz="8.72484e-05"/>
			<origin rpy="0 0 0" xyz="0.02556 -0.00281 0.00076"/>
		</inertial>
		<xacro:insert_visu_RForeArm/>
	</link>
	<joint name="RWristYaw" type="revolute">
		<parent link="RForeArm"/>
		<child link="r_wrist"/>
		<origin rpy="0 0 0" xyz="0.05595 0 0"/>
		<axis xyz="1.0 0 0"/>
		<limit effort="0.76" lower="-1.82387" upper="1.82387" velocity="24.6229"/>
	</joint>
	<link name="r_wrist">
		<inertial>
			<mass value="0.18533"/>
			<inertia ixx="7.05493e-05" ixy="5.71599e-06" ixz="-2.24744e-05" iyy="0.000356062" iyz="3.17771e-06" izz="0.000351919"/>
			<origin rpy="0 0 0" xyz="0.03434 0.00088 0.00308"/>
		</inertial>
		<xacro:insert_visu_r_wrist/>
	</link>
	<joint name="RHand" type="revolute">
		<parent link="r_wrist"/>
		<child link="r_gripper"/>
		<origin rpy="0 0 0" xyz="0.05775 0 -0.01231"/>
		<limit effort="0.177576" lower="0" upper="1.0" velocity="3"/>
	</joint>
	<link name="r_gripper">
		<inertial>
			<mass value="2e-06"/>
			<inertia ixx="1.1e-09" ixy="0" ixz="0" iyy="1.1e-09" iyz="0" izz="1.1e-09"/>
			<origin rpy="0 0 0" xyz="0 0 0"/>
		</inertial>
	</link>
</robot>
