<?xml version="1.0" ?>
<!-- =================================================================================== -->
<!-- |    This document was autogenerated by xacro from naorobot.xacro                 | -->
<!-- |    EDITING THIS FILE BY HAND IS NOT RECOMMENDED                                 | -->
<!-- =================================================================================== -->
<!-- ***************************************************************** 
 ****** File automatically generated by generate_urdf.py script ****** 
 ********************************************************************* -->
<robot name="naoH25V40" xmlns:xacro="http://www.ros.org/wiki/xacro">
  <joint name="LFinger1" type="revolute">
    <parent link="l_wrist"/>
    <child link="LFinger11"/>
    <origin rpy="0 0 0" xyz="0.06907 0.01157 -0.00304"/>
    <axis xyz="0 1 0"/>
    <mimic joint="LHand" multiplier="-0.785398163398" offset="0.785398163398"/>
    <limit effort="10.0" lower="0.0" upper="0.785398163398" velocity="3.0"/>
  </joint>
  <link name="LFinger11">
    <visual>
      <origin rpy="1.57079632679 0 1.57079632679" xyz="0.000718 0 0"/>
      <geometry>
        <box size="0.01 0.01 0.01436"/>
      </geometry>
      <material name="Yellow"/>
    </visual>
    <collision>
      <origin rpy="1.57079632679 0 1.57079632679" xyz="0.000718 0 0"/>
      <geometry>
        <box size="0.01 0.01 0.01436"/>
      </geometry>
    </collision>
    <inertial>
      <mass value="0.2e-5"/>
      <origin xyz="0 0 0"/>
      <inertia ixx="1e-9" ixy="0" ixz="0" iyy="1e-9" iyz="0" izz="1e-9"/>
    </inertial>
  </link>
  <joint name="LFinger1_1" type="revolute">
    <parent link="LFinger11"/>
    <child link="LFinger12"/>
    <origin rpy="0 0 0" xyz="0.01436 0 0"/>
    <axis xyz="0 1 0"/>
    <mimic joint="LHand" multiplier="-0.785398163398" offset="0.785398163398"/>
    <limit effort="10.0" lower="0.0" upper="0.785398163398" velocity="3.0"/>
  </joint>
  <link name="LFinger12">
    <visual>
      <origin rpy="1.57079632679 0 1.57079632679" xyz="0.000718 0 0"/>
      <geometry>
        <box size="0.01 0.01 0.01436"/>
      </geometry>
      <material name="Yellow"/>
    </visual>
    <collision>
      <origin rpy="1.57079632679 0 1.57079632679" xyz="0.000718 0 0"/>
      <geometry>
        <box size="0.01 0.01 0.01436"/>
      </geometry>
    </collision>
    <inertial>
      <mass value="0.2e-5"/>
      <origin xyz="0 0 0"/>
      <inertia ixx="1e-9" ixy="0" ixz="0" iyy="1e-9" iyz="0" izz="1e-9"/>
    </inertial>
  </link>
  <joint name="LFinger1_2" type="revolute">
    <parent link="LFinger12"/>
    <child link="LFinger13"/>
    <origin rpy="0 0 0" xyz="0.01436 0 0"/>
    <axis xyz="0 1 0"/>
    <mimic joint="LHand" multiplier="-0.785398163398" offset="0.785398163398"/>
    <limit effort="10.0" lower="0.0" upper="0.785398163398" velocity="3.0"/>
  </joint>
  <link name="LFinger13">
    <visual>
      <origin rpy="1.57079632679 0 1.57079632679" xyz="0.000718 0 0"/>
      <geometry>
        <box size="0.01 0.01 0.01436"/>
      </geometry>
      <material name="Yellow"/>
    </visual>
    <collision>
      <origin rpy="1.57079632679 0 1.57079632679" xyz="0.000718 0 0"/>
      <geometry>
        <box size="0.01 0.01 0.01436"/>
      </geometry>
    </collision>
    <inertial>
      <mass value="0.2e-5"/>
      <origin xyz="0 0 0"/>
      <inertia ixx="1e-9" ixy="0" ixz="0" iyy="1e-9" iyz="0" izz="1e-9"/>
    </inertial>
  </link>
  <joint name="LFinger2" type="revolute">
    <parent link="l_wrist"/>
    <child link="LFinger21"/>
    <origin rpy="0 0 0" xyz="0.06907 -0.01157 -0.00304"/>
    <axis xyz="0 1 0"/>
    <mimic joint="LHand" multiplier="-0.785398163398" offset="0.785398163398"/>
    <limit effort="10.0" lower="0.0" upper="0.785398163398" velocity="3.0"/>
  </joint>
  <link name="LFinger21">
    <visual>
      <origin rpy="1.57079632679 0 1.57079632679" xyz="0.000718 0 0"/>
      <geometry>
        <box size="0.01 0.01 0.01436"/>
      </geometry>
      <material name="Yellow"/>
    </visual>
    <collision>
      <origin rpy="1.57079632679 0 1.57079632679" xyz="0.000718 0 0"/>
      <geometry>
        <box size="0.01 0.01 0.01436"/>
      </geometry>
    </collision>
    <inertial>
      <mass value="0.2e-5"/>
      <origin xyz="0 0 0"/>
      <inertia ixx="1e-9" ixy="0" ixz="0" iyy="1e-9" iyz="0" izz="1e-9"/>
    </inertial>
  </link>
  <joint name="LFinger2_1" type="revolute">
    <parent link="LFinger21"/>
    <child link="LFinger22"/>
    <origin rpy="0 0 0" xyz="0.01436 0 0"/>
    <axis xyz="0 1 0"/>
    <mimic joint="LHand" multiplier="-0.785398163398" offset="0.785398163398"/>
    <limit effort="10.0" lower="0.0" upper="0.785398163398" velocity="3.0"/>
  </joint>
  <link name="LFinger22">
    <visual>
      <origin rpy="1.57079632679 0 1.57079632679" xyz="0.000718 0 0"/>
      <geometry>
        <box size="0.01 0.01 0.01436"/>
      </geometry>
      <material name="Yellow"/>
    </visual>
    <collision>
      <origin rpy="1.57079632679 0 1.57079632679" xyz="0.000718 0 0"/>
      <geometry>
        <box size="0.01 0.01 0.01436"/>
      </geometry>
    </collision>
    <inertial>
      <mass value="0.2e-5"/>
      <origin xyz="0 0 0"/>
      <inertia ixx="1e-9" ixy="0" ixz="0" iyy="1e-9" iyz="0" izz="1e-9"/>
    </inertial>
  </link>
  <joint name="LFinger2_2" type="revolute">
    <parent link="LFinger22"/>
    <child link="LFinger23"/>
    <origin rpy="0 0 0" xyz="0.01436 0 0"/>
    <axis xyz="0 1 0"/>
    <mimic joint="LHand" multiplier="-0.785398163398" offset="0.785398163398"/>
    <limit effort="10.0" lower="0.0" upper="0.785398163398" velocity="3.0"/>
  </joint>
  <link name="LFinger23">
    <visual>
      <origin rpy="1.57079632679 0 1.57079632679" xyz="0.000718 0 0"/>
      <geometry>
        <box size="0.01 0.01 0.01436"/>
      </geometry>
      <material name="Yellow"/>
    </visual>
    <collision>
      <origin rpy="1.57079632679 0 1.57079632679" xyz="0.000718 0 0"/>
      <geometry>
        <box size="0.01 0.01 0.01436"/>
      </geometry>
    </collision>
    <inertial>
      <mass value="0.2e-5"/>
      <origin xyz="0 0 0"/>
      <inertia ixx="1e-9" ixy="0" ixz="0" iyy="1e-9" iyz="0" izz="1e-9"/>
    </inertial>
  </link>
  <joint name="RFinger1" type="revolute">
    <parent link="r_wrist"/>
    <child link="RFinger11"/>
    <origin rpy="0 0 0" xyz="0.06907 0.01157 -0.00304"/>
    <axis xyz="0 1 0"/>
    <mimic joint="RHand" multiplier="-0.785398163398" offset="0.785398163398"/>
    <limit effort="10.0" lower="0.0" upper="0.785398163398" velocity="3.0"/>
  </joint>
  <link name="RFinger11">
    <visual>
      <origin rpy="1.57079632679 0 1.57079632679" xyz="0.000718 0 0"/>
      <geometry>
        <box size="0.01 0.01 0.01436"/>
      </geometry>
      <material name="Yellow"/>
    </visual>
    <collision>
      <origin rpy="1.57079632679 0 1.57079632679" xyz="0.000718 0 0"/>
      <geometry>
        <box size="0.01 0.01 0.01436"/>
      </geometry>
    </collision>
    <inertial>
      <mass value="0.2e-5"/>
      <origin xyz="0 0 0"/>
      <inertia ixx="1e-9" ixy="0" ixz="0" iyy="1e-9" iyz="0" izz="1e-9"/>
    </inertial>
  </link>
  <joint name="RFinger1_1" type="revolute">
    <parent link="RFinger11"/>
    <child link="RFinger12"/>
    <origin rpy="0 0 0" xyz="0.01436 0 0"/>
    <axis xyz="0 1 0"/>
    <mimic joint="RHand" multiplier="-0.785398163398" offset="0.785398163398"/>
    <limit effort="10.0" lower="0.0" upper="0.785398163398" velocity="3.0"/>
  </joint>
  <link name="RFinger12">
    <visual>
      <origin rpy="1.57079632679 0 1.57079632679" xyz="0.000718 0 0"/>
      <geometry>
        <box size="0.01 0.01 0.01436"/>
      </geometry>
      <material name="Yellow"/>
    </visual>
    <collision>
      <origin rpy="1.57079632679 0 1.57079632679" xyz="0.000718 0 0"/>
      <geometry>
        <box size="0.01 0.01 0.01436"/>
      </geometry>
    </collision>
    <inertial>
      <mass value="0.2e-5"/>
      <origin xyz="0 0 0"/>
      <inertia ixx="1e-9" ixy="0" ixz="0" iyy="1e-9" iyz="0" izz="1e-9"/>
    </inertial>
  </link>
  <joint name="RFinger1_2" type="revolute">
    <parent link="RFinger12"/>
    <child link="RFinger13"/>
    <origin rpy="0 0 0" xyz="0.01436 0 0"/>
    <axis xyz="0 1 0"/>
    <mimic joint="RHand" multiplier="-0.785398163398" offset="0.785398163398"/>
    <limit effort="10.0" lower="0.0" upper="0.785398163398" velocity="3.0"/>
  </joint>
  <link name="RFinger13">
    <visual>
      <origin rpy="1.57079632679 0 1.57079632679" xyz="0.000718 0 0"/>
      <geometry>
        <box size="0.01 0.01 0.01436"/>
      </geometry>
      <material name="Yellow"/>
    </visual>
    <collision>
      <origin rpy="1.57079632679 0 1.57079632679" xyz="0.000718 0 0"/>
      <geometry>
        <box size="0.01 0.01 0.01436"/>
      </geometry>
    </collision>
    <inertial>
      <mass value="0.2e-5"/>
      <origin xyz="0 0 0"/>
      <inertia ixx="1e-9" ixy="0" ixz="0" iyy="1e-9" iyz="0" izz="1e-9"/>
    </inertial>
  </link>
  <joint name="RFinger2" type="revolute">
    <parent link="r_wrist"/>
    <child link="RFinger21"/>
    <origin rpy="0 0 0" xyz="0.06907 -0.01157 -0.00304"/>
    <axis xyz="0 1 0"/>
    <mimic joint="RHand" multiplier="-0.785398163398" offset="0.785398163398"/>
    <limit effort="10.0" lower="0.0" upper="0.785398163398" velocity="3.0"/>
  </joint>
  <link name="RFinger21">
    <visual>
      <origin rpy="1.57079632679 0 1.57079632679" xyz="0.000718 0 0"/>
      <geometry>
        <box size="0.01 0.01 0.01436"/>
      </geometry>
      <material name="Yellow"/>
    </visual>
    <collision>
      <origin rpy="1.57079632679 0 1.57079632679" xyz="0.000718 0 0"/>
      <geometry>
        <box size="0.01 0.01 0.01436"/>
      </geometry>
    </collision>
    <inertial>
      <mass value="0.2e-5"/>
      <origin xyz="0 0 0"/>
      <inertia ixx="1e-9" ixy="0" ixz="0" iyy="1e-9" iyz="0" izz="1e-9"/>
    </inertial>
  </link>
  <joint name="RFinger2_1" type="revolute">
    <parent link="RFinger21"/>
    <child link="RFinger22"/>
    <origin rpy="0 0 0" xyz="0.01436 0 0"/>
    <axis xyz="0 1 0"/>
    <mimic joint="RHand" multiplier="-0.785398163398" offset="0.785398163398"/>
    <limit effort="10.0" lower="0.0" upper="0.785398163398" velocity="3.0"/>
  </joint>
  <link name="RFinger22">
    <visual>
      <origin rpy="1.57079632679 0 1.57079632679" xyz="0.000718 0 0"/>
      <geometry>
        <box size="0.01 0.01 0.01436"/>
      </geometry>
      <material name="Yellow"/>
    </visual>
    <collision>
      <origin rpy="1.57079632679 0 1.57079632679" xyz="0.000718 0 0"/>
      <geometry>
        <box size="0.01 0.01 0.01436"/>
      </geometry>
    </collision>
    <inertial>
      <mass value="0.2e-5"/>
      <origin xyz="0 0 0"/>
      <inertia ixx="1e-9" ixy="0" ixz="0" iyy="1e-9" iyz="0" izz="1e-9"/>
    </inertial>
  </link>
  <joint name="RFinger2_2" type="revolute">
    <parent link="RFinger22"/>
    <child link="RFinger23"/>
    <origin rpy="0 0 0" xyz="0.01436 0 0"/>
    <axis xyz="0 1 0"/>
    <mimic joint="RHand" multiplier="-0.785398163398" offset="0.785398163398"/>
    <limit effort="10.0" lower="0.0" upper="0.785398163398" velocity="3.0"/>
  </joint>
  <link name="RFinger23">
    <visual>
      <origin rpy="1.57079632679 0 1.57079632679" xyz="0.000718 0 0"/>
      <geometry>
        <box size="0.01 0.01 0.01436"/>
      </geometry>
      <material name="Yellow"/>
    </visual>
    <collision>
      <origin rpy="1.57079632679 0 1.57079632679" xyz="0.000718 0 0"/>
      <geometry>
        <box size="0.01 0.01 0.01436"/>
      </geometry>
    </collision>
    <inertial>
      <mass value="0.2e-5"/>
      <origin xyz="0 0 0"/>
      <inertia ixx="1e-9" ixy="0" ixz="0" iyy="1e-9" iyz="0" izz="1e-9"/>
    </inertial>
  </link>
  <joint name="LThumb1_joint" type="revolute">
    <parent link="l_wrist"/>
    <child link="LThumb1"/>
    <origin rpy="3.14159265359 0.785398163398 0" xyz="0.04895 0 -0.02638"/>
    <axis xyz="0 1 0"/>
    <mimic joint="LHand" multiplier="-0.785398163398" offset="0.785398163398"/>
    <limit effort="10.0" lower="0.0" upper="0.785398163398" velocity="3.0"/>
  </joint>
  <link name="LThumb1">
    <visual>
      <origin rpy="1.57079632679 0 1.57079632679" xyz="0.000718 0 0"/>
      <geometry>
        <box size="0.01 0.01 0.01436"/>
      </geometry>
      <material name="Yellow"/>
    </visual>
    <collision>
      <origin rpy="1.57079632679 0 1.57079632679" xyz="0.000718 0 0"/>
      <geometry>
        <box size="0.01 0.01 0.01436"/>
      </geometry>
    </collision>
    <inertial>
      <mass value="0.2e-5"/>
      <origin xyz="0 0 0"/>
      <inertia ixx="1e-9" ixy="0" ixz="0" iyy="1e-9" iyz="0" izz="1e-9"/>
    </inertial>
  </link>
  <joint name="LThumb1_2" type="revolute">
    <parent link="LThumb1"/>
    <child link="LThumb2"/>
    <origin rpy="0 0 0" xyz="0.01436 0 0"/>
    <axis xyz="0 1 0"/>
    <mimic joint="LHand" multiplier="-0.785398163398" offset="0.785398163398"/>
    <limit effort="10.0" lower="0.0" upper="0.785398163398" velocity="3.0"/>
  </joint>
  <link name="LThumb2">
    <visual>
      <origin rpy="1.57079632679 0 1.57079632679" xyz="0.000718 0 0"/>
      <geometry>
        <box size="0.01 0.01 0.01436"/>
      </geometry>
      <material name="Yellow"/>
    </visual>
    <collision>
      <origin rpy="1.57079632679 0 1.57079632679" xyz="0.000718 0 0"/>
      <geometry>
        <box size="0.01 0.01 0.01436"/>
      </geometry>
    </collision>
    <inertial>
      <mass value="0.2e-5"/>
      <origin xyz="0 0 0"/>
      <inertia ixx="1e-9" ixy="0" ixz="0" iyy="1e-9" iyz="0" izz="1e-9"/>
    </inertial>
  </link>
  <joint name="RThumb1_joint" type="revolute">
    <parent link="r_wrist"/>
    <child link="RThumb1"/>
    <origin rpy="3.14159265359 0.785398163398 0" xyz="0.04895 0 -0.02638"/>
    <axis xyz="0 1 0"/>
    <mimic joint="RHand" multiplier="-0.785398163398" offset="0.785398163398"/>
    <limit effort="10.0" lower="0.0" upper="0.785398163398" velocity="3.0"/>
  </joint>
  <link name="RThumb1">
    <visual>
      <origin rpy="1.57079632679 0 1.57079632679" xyz="0.000718 0 0"/>
      <geometry>
        <box size="0.01 0.01 0.01436"/>
      </geometry>
      <material name="Yellow"/>
    </visual>
    <collision>
      <origin rpy="1.57079632679 0 1.57079632679" xyz="0.000718 0 0"/>
      <geometry>
        <box size="0.01 0.01 0.01436"/>
      </geometry>
    </collision>
    <inertial>
      <mass value="0.2e-5"/>
      <origin xyz="0 0 0"/>
      <inertia ixx="1e-9" ixy="0" ixz="0" iyy="1e-9" iyz="0" izz="1e-9"/>
    </inertial>
  </link>
  <joint name="RThumb1_2" type="revolute">
    <parent link="RThumb1"/>
    <child link="RThumb2"/>
    <origin rpy="0 0 0" xyz="0.01436 0 0"/>
    <axis xyz="0 1 0"/>
    <mimic joint="RHand" multiplier="-0.785398163398" offset="0.785398163398"/>
    <limit effort="10.0" lower="0.0" upper="0.785398163398" velocity="3.0"/>
  </joint>
  <link name="RThumb2">
    <visual>
      <origin rpy="1.57079632679 0 1.57079632679" xyz="0.000718 0 0"/>
      <geometry>
        <box size="0.01 0.01 0.01436"/>
      </geometry>
      <material name="Yellow"/>
    </visual>
    <collision>
      <origin rpy="1.57079632679 0 1.57079632679" xyz="0.000718 0 0"/>
      <geometry>
        <box size="0.01 0.01 0.01436"/>
      </geometry>
    </collision>
    <inertial>
      <mass value="0.2e-5"/>
      <origin xyz="0 0 0"/>
      <inertia ixx="1e-9" ixy="0" ixz="0" iyy="1e-9" iyz="0" izz="1e-9"/>
    </inertial>
  </link>
  <joint name="HeadYaw" type="revolute">
    <parent link="torso"/>
    <child link="Neck"/>
    <origin rpy="0 0 0" xyz="0 0 0.1265"/>
    <axis xyz="0 0 1.0"/>
    <limit effort="1.2" lower="-2.08567" upper="2.08567" velocity="8.26797"/>
  </joint>
  <link name="Neck">
    <inertial>
      <mass value="0.05959"/>
      <inertia ixx="6.22337e-05" ixy="0" ixz="-7.448e-08" iyy="6.32443e-05" iyz="-1.0416e-07" izz="5.49462e-06"/>
      <origin rpy="0 0 0" xyz="-3e-05 0 -0.02573"/>
    </inertial>
  </link>
  <joint name="HeadPitch" type="revolute">
    <parent link="Neck"/>
    <child link="Head"/>
    <origin rpy="0 0 0" xyz="0 0 0"/>
    <axis xyz="0 1.0 0"/>
    <limit effort="1.2" lower="-0.671952" upper="0.514872" velocity="7.19407"/>
  </joint>
  <link name="Head">
    <inertial>
      <mass value="0.47672"/>
      <inertia ixx="0.00487953" ixy="1.42859e-05" ixz="0.000195457" iyy="0.00470361" iyz="-2.22459e-05" izz="0.00156714"/>
      <origin rpy="0 0 0" xyz="0.00383 0 0.05156"/>
    </inertial>
    <visual>
      <geometry>
        <cylinder length="0.14" radius="0.04"/>
      </geometry>
      <origin rpy="1.57079632679 0 0" xyz="0 0 0.058"/>
      <material name="LightGrey"/>
    </visual>
    <collision>
      <geometry>
        <cylinder length="0.14" radius="0.04"/>
      </geometry>
      <origin rpy="1.57079632679 0 0" xyz="0 0 0.058"/>
    </collision>
  </link>
  <joint name="gaze_joint" type="fixed">
    <parent link="Head"/>
    <child link="gaze"/>
    <origin rpy="0 0 0" xyz="0.0539 0 0.0679"/>
  </joint>
  <link name="gaze"/>
  <joint name="LHipYawPitch" type="revolute">
    <parent link="torso"/>
    <child link="LPelvis"/>
    <origin rpy="0 0 0" xyz="0 0.05 -0.085"/>
    <axis xyz="0 0.707106 -0.707106"/>
    <limit effort="3.2" lower="-1.14529" upper="0.740718" velocity="4.16174"/>
  </joint>
  <link name="LPelvis">
    <inertial>
      <mass value="0.07244"/>
      <inertia ixx="9.06449e-05" ixy="-4.88819e-06" ixz="1.22192e-05" iyy="0.000106658" iyz="2.78382e-05" izz="6.74286e-05"/>
      <origin rpy="0 0 0" xyz="-0.00717 -0.01187 0.02705"/>
    </inertial>
  </link>
  <joint name="LHipRoll" type="revolute">
    <parent link="LPelvis"/>
    <child link="LHip"/>
    <origin rpy="0 0 0" xyz="0 0 0"/>
    <axis xyz="1.0 0 0"/>
    <limit effort="3.2" lower="-0.379435" upper="0.79046" velocity="4.16174"/>
  </joint>
  <link name="LHip">
    <inertial>
      <mass value="0.1353"/>
      <inertia ixx="2.79131e-05" ixy="4.982e-08" ixz="-5.30968e-06" iyy="0.000101469" iyz="0" izz="0.000292094"/>
      <origin rpy="0 0 0" xyz="-0.01649 0.00029 -0.00475"/>
    </inertial>
  </link>
  <joint name="LHipPitch" type="revolute">
    <parent link="LHip"/>
    <child link="LThigh"/>
    <origin rpy="0 0 0" xyz="0 0 0"/>
    <axis xyz="0 1.0 0"/>
    <limit effort="3.2" lower="-1.53589" upper="0.48398" velocity="6.40239"/>
  </joint>
  <link name="LThigh">
    <inertial>
      <mass value="0.39798"/>
      <inertia ixx="0.00166559" ixy="4.3251e-07" ixz="8.25051e-05" iyy="0.001625" iyz="3.17428e-05" izz="0.000304929"/>
      <origin rpy="0 0 0" xyz="0.00131 0.00201 -0.05386"/>
    </inertial>
    <visual>
      <geometry>
        <cylinder length="0.1" radius="0.015"/>
      </geometry>
      <origin rpy="0 0 0" xyz="0 0 -0.05"/>
      <material name="LightGrey"/>
    </visual>
    <collision>
      <geometry>
        <cylinder length="0.1" radius="0.015"/>
      </geometry>
      <origin rpy="0 0 0" xyz="0 0 -0.05"/>
    </collision>
  </link>
  <joint name="LKneePitch" type="revolute">
    <parent link="LThigh"/>
    <child link="LTibia"/>
    <origin rpy="0 0 0" xyz="0 0 -0.1"/>
    <axis xyz="0 1.0 0"/>
    <limit effort="3.2" lower="-0.0923279" upper="2.11255" velocity="6.40239"/>
  </joint>
  <link name="LTibia">
    <inertial>
      <mass value="0.29714"/>
      <inertia ixx="0.00118034" ixy="3.0542e-07" ixz="4.0171e-05" iyy="0.00112928" iyz="3.57364e-05" izz="0.00019349"/>
      <origin rpy="0 0 0" xyz="0.00471 0.0021 -0.04891"/>
    </inertial>
    <visual>
      <geometry>
        <cylinder length="0.1" radius="0.015"/>
      </geometry>
      <origin rpy="0 0 0" xyz="0 0 -0.05"/>
      <material name="LightGrey"/>
    </visual>
    <collision>
      <geometry>
        <cylinder length="0.1" radius="0.015"/>
      </geometry>
      <origin rpy="0 0 0" xyz="0 0 -0.05"/>
    </collision>
  </link>
  <joint name="LAnklePitch" type="revolute">
    <parent link="LTibia"/>
    <child link="l_ankle"/>
    <origin rpy="0 0 0" xyz="0 0 -0.1029"/>
    <axis xyz="0 1.0 0"/>
    <limit effort="3.2" lower="-1.18944" upper="0.922581" velocity="6.40239"/>
  </joint>
  <link name="l_ankle">
    <inertial>
      <mass value="0.13892"/>
      <inertia ixx="3.88258e-05" ixy="-4.942e-08" ixz="2.21321e-06" iyy="7.21158e-05" iyz="6.74e-09" izz="5.35199e-05"/>
      <origin rpy="0 0 0" xyz="0.00142 0.00028 0.00638"/>
    </inertial>
  </link>
  <joint name="LAnkleRoll" type="revolute">
    <parent link="l_ankle"/>
    <child link="l_sole"/>
    <origin rpy="0 0 0" xyz="0 0 0"/>
    <axis xyz="1.0 0 0"/>
    <limit effort="3.2" lower="-0.397761" upper="0.768992" velocity="4.16174"/>
  </joint>
  <link name="l_sole">
    <inertial>
      <mass value="0.16304"/>
      <inertia ixx="0.000267598" ixy="-5.92718e-06" ixz="0.000137299" iyy="0.000643148" iyz="1.86977e-05" izz="0.000526497"/>
      <origin rpy="0 0 0" xyz="0.02489 0.0033 -0.03208"/>
    </inertial>
    <visual>
      <geometry>
        <box size="0.16 0.06 0.015"/>
      </geometry>
      <origin rpy="0 0 0" xyz="0.02 0 0.0075"/>
      <material name="LightGrey"/>
    </visual>
    <collision>
      <geometry>
        <box size="0.16 0.06 0.015"/>
      </geometry>
      <origin rpy="0 0 0" xyz="0.02 0 0.0075"/>
    </collision>
  </link>
  <joint name="RHipYawPitch" type="revolute">
    <parent link="torso"/>
    <child link="RPelvis"/>
    <origin rpy="0 0 0" xyz="0 -0.05 -0.085"/>
    <axis xyz="0 0.707106 0.707106"/>
    <limit effort="3.2" lower="-1.14529" upper="0.740718" velocity="4.16174"/>
  </joint>
  <link name="RPelvis">
    <inertial>
      <mass value="0.07244"/>
      <inertia ixx="9.06449e-05" ixy="4.88819e-06" ixz="1.22192e-05" iyy="0.000106658" iyz="-2.78382e-05" izz="6.74286e-05"/>
      <origin rpy="0 0 0" xyz="-0.00717 0.01187 0.02705"/>
    </inertial>
  </link>
  <joint name="RHipRoll" type="revolute">
    <parent link="RPelvis"/>
    <child link="RHip"/>
    <origin rpy="0 0 0" xyz="0 0 0"/>
    <axis xyz="1.0 0 0"/>
    <limit effort="3.2" lower="-0.79046" upper="0.379435" velocity="4.16174"/>
  </joint>
  <link name="RHip">
    <inertial>
      <mass value="0.1353"/>
      <inertia ixx="2.79131e-05" ixy="-4.982e-08" ixz="-5.30968e-06" iyy="0.000101469" iyz="0" izz="0.000292094"/>
      <origin rpy="0 0 0" xyz="-0.01649 -0.00029 -0.00475"/>
    </inertial>
  </link>
  <joint name="RHipPitch" type="revolute">
    <parent link="RHip"/>
    <child link="RThigh"/>
    <origin rpy="0 0 0" xyz="0 0 0"/>
    <axis xyz="0 1.0 0"/>
    <limit effort="3.2" lower="-1.53589" upper="0.48398" velocity="6.40239"/>
  </joint>
  <link name="RThigh">
    <inertial>
      <mass value="0.39798"/>
      <inertia ixx="0.00166559" ixy="-4.3251e-07" ixz="8.25051e-05" iyy="0.001625" iyz="-3.17428e-05" izz="0.000304929"/>
      <origin rpy="0 0 0" xyz="0.00131 -0.00201 -0.05386"/>
    </inertial>
    <visual>
      <geometry>
        <cylinder length="0.1" radius="0.015"/>
      </geometry>
      <origin rpy="0 0 0" xyz="0 0 -0.05"/>
      <material name="LightGrey"/>
    </visual>
    <collision>
      <geometry>
        <cylinder length="0.1" radius="0.015"/>
      </geometry>
      <origin rpy="0 0 0" xyz="0 0 -0.05"/>
    </collision>
  </link>
  <joint name="RKneePitch" type="revolute">
    <parent link="RThigh"/>
    <child link="RTibia"/>
    <origin rpy="0 0 0" xyz="0 0 -0.1"/>
    <axis xyz="0 1.0 0"/>
    <limit effort="3.2" lower="-0.0923279" upper="2.11255" velocity="6.40239"/>
  </joint>
  <link name="RTibia">
    <inertial>
      <mass value="0.29714"/>
      <inertia ixx="0.00118034" ixy="-3.0542e-07" ixz="4.0171e-05" iyy="0.00112928" iyz="-3.57364e-05" izz="0.00019349"/>
      <origin rpy="0 0 0" xyz="0.00471 -0.0021 -0.04891"/>
    </inertial>
    <visual>
      <geometry>
        <cylinder length="0.1" radius="0.015"/>
      </geometry>
      <origin rpy="0 0 0" xyz="0 0 -0.05"/>
      <material name="LightGrey"/>
    </visual>
    <collision>
      <geometry>
        <cylinder length="0.1" radius="0.015"/>
      </geometry>
      <origin rpy="0 0 0" xyz="0 0 -0.05"/>
    </collision>
  </link>
  <joint name="RAnklePitch" type="revolute">
    <parent link="RTibia"/>
    <child link="r_ankle"/>
    <origin rpy="0 0 0" xyz="0 0 -0.1029"/>
    <axis xyz="0 1.0 0"/>
    <limit effort="3.2" lower="-1.1863" upper="0.932006" velocity="6.40239"/>
  </joint>
  <link name="r_ankle">
    <inertial>
      <mass value="0.13892"/>
      <inertia ixx="3.88258e-05" ixy="4.942e-08" ixz="2.21321e-06" iyy="7.21158e-05" iyz="-6.74e-09" izz="5.35199e-05"/>
      <origin rpy="0 0 0" xyz="0.00142 -0.00028 0.00638"/>
    </inertial>
  </link>
  <joint name="RAnkleRoll" type="revolute">
    <parent link="r_ankle"/>
    <child link="r_sole"/>
    <origin rpy="0 0 0" xyz="0 0 0"/>
    <axis xyz="1.0 0 0"/>
    <limit effort="3.2" lower="-0.768992" upper="0.397935" velocity="4.16174"/>
  </joint>
  <link name="r_sole">
    <inertial>
      <mass value="0.16304"/>
      <inertia ixx="0.000267598" ixy="5.92718e-06" ixz="1.37299e-05" iyy="0.000643148" iyz="-1.86977e-05" izz="0.000526497"/>
      <origin rpy="0 0 0" xyz="0.02489 -0.0033 -0.03208"/>
    </inertial>
    <visual>
      <geometry>
        <box size="0.16 0.06 0.015"/>
      </geometry>
      <origin rpy="0 0 0" xyz="0.02 0 0.0075"/>
      <material name="LightGrey"/>
    </visual>
    <collision>
      <geometry>
        <box size="0.16 0.06 0.015"/>
      </geometry>
      <origin rpy="0 0 0" xyz="0.02 0 0.0075"/>
    </collision>
  </link>
  <link name="base_link"/>
  <joint name="base_joint" type="fixed">
    <parent link="base_link"/>
    <child link="torso"/>
    <origin rpy="0 0 0" xyz="0 0 0"/>
  </joint>
  <link name="torso">
    <inertial>
      <mass value="1.02628"/>
      <inertia ixx="0.00487953" ixy="1.42859e-05" ixz="0.000195457" iyy="0.00470361" iyz="-2.22459e-05" izz="0.00156714"/>
      <origin rpy="0 0 0" xyz="-0.0048 0 0.04227"/>
    </inertial>
    <visual>
      <geometry>
        <cylinder length="0.2115" radius="0.015"/>
      </geometry>
      <origin rpy="0 0 0" xyz="0 0 0.02075"/>
      <material name="LightGrey"/>
    </visual>
    <collision>
      <geometry>
        <cylinder length="0.2115" radius="0.015"/>
      </geometry>
      <origin rpy="0 0 0" xyz="0 0 0.02075"/>
    </collision>
  </link>
  <joint name="LShoulderPitch" type="revolute">
    <parent link="torso"/>
    <child link="LShoulder"/>
    <origin rpy="0 0 0" xyz="0 0.098 0.1"/>
    <axis xyz="0 1.0 0"/>
    <limit effort="1.2" lower="-2.08567" upper="2.08567" velocity="8.26797"/>
  </joint>
  <link name="LShoulder">
    <inertial>
      <mass value="0.06984"/>
      <inertia ixx="7.10185e-05" ixy="-2.02458e-06" ixz="1.713e-08" iyy="1.40492e-05" iyz="-4.41e-08" izz="7.31447e-05"/>
      <origin rpy="0 0 0" xyz="-0.00178 -0.02507 0.00019"/>
    </inertial>
  </link>
  <joint name="LShoulderRoll" type="revolute">
    <parent link="LShoulder"/>
    <child link="LBicep"/>
    <origin rpy="0 0 0" xyz="0 0 0"/>
    <axis xyz="0 0 1.0"/>
    <limit effort="1.2" lower="0.00872665" upper="1.64934" velocity="7.19407"/>
  </joint>
  <link name="LBicep">
    <inertial>
      <mass value="0.12166"/>
      <inertia ixx="5.93179e-05" ixy="-1.93929e-06" ixz="-1.5645e-06" iyy="0.000202211" iyz="-3.68731e-06" izz="0.000184216"/>
      <origin rpy="0 0 0" xyz="0.02067 0.00388 0.00362"/>
    </inertial>
    <visual>
      <geometry>
        <cylinder length="0.09" radius="0.015"/>
      </geometry>
      <origin rpy="1.57079632679 0 1.57079632679" xyz="0.045 0 0"/>
      <material name="LightGrey"/>
    </visual>
    <collision>
      <geometry>
        <cylinder length="0.09" radius="0.015"/>
      </geometry>
      <origin rpy="1.57079632679 0 1.57079632679" xyz="0.045 0 0"/>
    </collision>
  </link>
  <joint name="LElbowYaw" type="revolute">
    <parent link="LBicep"/>
    <child link="LElbow"/>
    <origin rpy="0 0 0" xyz="0.09 0 0"/>
    <axis xyz="1.0 0 0"/>
    <limit effort="1.2" lower="-2.08567" upper="2.08567" velocity="8.26797"/>
  </joint>
  <link name="LElbow">
    <inertial>
      <mass value="0.05959"/>
      <inertia ixx="5.49462e-06" ixy="-2.242e-08" ixz="6.771e-08" iyy="6.22479e-05" iyz="5.59e-09" izz="6.32301e-05"/>
      <origin rpy="0 0 0" xyz="-0.02573 -1e-05 -0.0002"/>
    </inertial>
  </link>
  <joint name="LElbowRoll" type="revolute">
    <parent link="LElbow"/>
    <child link="LForeArm"/>
    <origin rpy="0 0 0" xyz="0 0 0"/>
    <axis xyz="0 0 1.0"/>
    <limit effort="1.2" lower="-1.56207" upper="-0.00872665" velocity="7.19407"/>
  </joint>
  <link name="LForeArm">
    <inertial>
      <mass value="0.0377"/>
      <inertia ixx="1.2711e-05" ixy="-1.3146e-06" ixz="-1.43626e-06" iyy="3.0569e-05" iyz="-2.0686e-07" izz="2.97629e-05"/>
      <origin rpy="0 0 0" xyz="0.0194 0.00304 0.0025"/>
    </inertial>
    <visual>
      <geometry>
        <cylinder length="0.05065" radius="0.015"/>
      </geometry>
      <origin rpy="1.57079632679 0 1.57079632679" xyz="0.025325 0 0"/>
      <material name="LightGrey"/>
    </visual>
    <collision>
      <geometry>
        <cylinder length="0.05065" radius="0.015"/>
      </geometry>
      <origin rpy="1.57079632679 0 1.57079632679" xyz="0.025325 0 0"/>
    </collision>
  </link>
  <joint name="LWristYaw" type="revolute">
    <parent link="LForeArm"/>
    <child link="l_wrist"/>
    <origin rpy="0 0 0" xyz="0.05055 0 0"/>
    <axis xyz="1.0 0 0"/>
    <limit effort="0.3891" lower="-1.82387" upper="1.82387" velocity="5.03144"/>
  </joint>
  <link name="l_wrist">
    <inertial>
      <mass value="0.14314"/>
      <inertia ixx="5.69262e-05" ixy="-8.22213e-06" ixz="1.13629e-05" iyy="0.000272309" iyz="1.8178e-06" izz="0.000266114"/>
      <origin rpy="0 0 0" xyz="0.03241 0.00268 -0.00272"/>
    </inertial>
    <visual>
      <geometry>
        <cylinder length="0.058" radius="0.015"/>
      </geometry>
      <origin rpy="1.57079632679 0 1.57079632679" xyz="0.029 0 0"/>
      <material name="LightGrey"/>
    </visual>
    <collision>
      <geometry>
        <cylinder length="0.058" radius="0.015"/>
      </geometry>
      <origin rpy="1.57079632679 0 1.57079632679" xyz="0.029 0 0"/>
    </collision>
  </link>
  <joint name="LHand" type="revolute">
    <parent link="l_wrist"/>
    <child link="l_gripper"/>
    <origin rpy="0 0 0" xyz="0.058 0 -0.0159"/>
    <limit effort="0.177576" lower="0" upper="1.0" velocity="3"/>
  </joint>
  <link name="l_gripper">
    <inertial>
      <mass value="2e-06"/>
      <inertia ixx="1.1e-09" ixy="0" ixz="0" iyy="1.1e-09" iyz="0" izz="1.1e-09"/>
      <origin rpy="0 0 0" xyz="0 0 0"/>
    </inertial>
  </link>
  <joint name="RShoulderPitch" type="revolute">
    <parent link="torso"/>
    <child link="RShoulder"/>
    <origin rpy="0 0 0" xyz="0 -0.098 0.1"/>
    <axis xyz="0 1.0 0"/>
    <limit effort="1.2" lower="-2.08567" upper="2.08567" velocity="8.26797"/>
  </joint>
  <link name="RShoulder">
    <inertial>
      <mass value="0.06984"/>
      <inertia ixx="7.10185e-05" ixy="2.02458e-06" ixz="1.713e-08" iyy="1.40492e-05" iyz="4.41e-08" izz="7.31447e-05"/>
      <origin rpy="0 0 0" xyz="-0.00178 0.02507 0.00019"/>
    </inertial>
  </link>
  <joint name="RShoulderRoll" type="revolute">
    <parent link="RShoulder"/>
    <child link="RBicep"/>
    <origin rpy="0 0 0" xyz="0 0 0"/>
    <axis xyz="0 0 1.0"/>
    <limit effort="1.2" lower="-1.64934" upper="-0.00872665" velocity="7.19407"/>
  </joint>
  <link name="RBicep">
    <inertial>
      <mass value="0.12166"/>
      <inertia ixx="5.93179e-05" ixy="1.93929e-06" ixz="-1.5645e-05" iyy="0.000202211" iyz="3.68731e-06" izz="0.000184216"/>
      <origin rpy="0 0 0" xyz="0.02067 -0.00388 0.00362"/>
    </inertial>
    <visual>
      <geometry>
        <cylinder length="0.09" radius="0.015"/>
      </geometry>
      <origin rpy="1.57079632679 0 1.57079632679" xyz="0.045 0 0"/>
      <material name="LightGrey"/>
    </visual>
    <collision>
      <geometry>
        <cylinder length="0.09" radius="0.015"/>
      </geometry>
      <origin rpy="1.57079632679 0 1.57079632679" xyz="0.045 0 0"/>
    </collision>
  </link>
  <joint name="RElbowYaw" type="revolute">
    <parent link="RBicep"/>
    <child link="RElbow"/>
    <origin rpy="0 0 0" xyz="0.09 0 0"/>
    <axis xyz="1.0 0 0"/>
    <limit effort="1.2" lower="-2.08567" upper="2.08567" velocity="8.26797"/>
  </joint>
  <link name="RElbow">
    <inertial>
      <mass value="0.05959"/>
      <inertia ixx="5.49462e-06" ixy="2.242e-08" ixz="6.771e-08" iyy="6.22479e-05" iyz="-5.59e-09" izz="6.32301e-05"/>
      <origin rpy="0 0 0" xyz="-0.02573 1e-05 -0.0002"/>
    </inertial>
  </link>
  <joint name="RElbowRoll" type="revolute">
    <parent link="RElbow"/>
    <child link="RForeArm"/>
    <origin rpy="0 0 0" xyz="0 0 0"/>
    <axis xyz="0 0 1.0"/>
    <limit effort="1.2" lower="0.00872665" upper="1.56207" velocity="7.19407"/>
  </joint>
  <link name="RForeArm">
    <inertial>
      <mass value="0.0377"/>
      <inertia ixx="1.2711e-05" ixy="1.3146e-06" ixz="-1.43626e-06" iyy="3.0569e-05" iyz="2.0686e-07" izz="2.97629e-05"/>
      <origin rpy="0 0 0" xyz="0.0194 -0.00304 0.0025"/>
    </inertial>
    <visual>
      <geometry>
        <cylinder length="0.05065" radius="0.015"/>
      </geometry>
      <origin rpy="1.57079632679 0 1.57079632679" xyz="0.025325 0 0"/>
      <material name="LightGrey"/>
    </visual>
    <collision>
      <geometry>
        <cylinder length="0.05065" radius="0.015"/>
      </geometry>
      <origin rpy="1.57079632679 0 1.57079632679" xyz="0.025325 0 0"/>
    </collision>
  </link>
  <joint name="RWristYaw" type="revolute">
    <parent link="RForeArm"/>
    <child link="r_wrist"/>
    <origin rpy="0 0 0" xyz="0.05055 0 0"/>
    <axis xyz="1.0 0 0"/>
    <limit effort="0.3891" lower="-1.82387" upper="1.82387" velocity="5.03144"/>
  </joint>
  <link name="r_wrist">
    <inertial>
      <mass value="0.14314"/>
      <inertia ixx="5.69262e-05" ixy="8.22213e-06" ixz="1.13629e-05" iyy="0.000272309" iyz="-1.8178e-06" izz="0.000266114"/>
      <origin rpy="0 0 0" xyz="0.03241 -0.00268 -0.00272"/>
    </inertial>
    <visual>
      <geometry>
        <cylinder length="0.058" radius="0.015"/>
      </geometry>
      <origin rpy="1.57079632679 0 1.57079632679" xyz="0.029 0 0"/>
      <material name="LightGrey"/>
    </visual>
    <collision>
      <geometry>
        <cylinder length="0.058" radius="0.015"/>
      </geometry>
      <origin rpy="1.57079632679 0 1.57079632679" xyz="0.029 0 0"/>
    </collision>
  </link>
  <joint name="RHand" type="revolute">
    <parent link="r_wrist"/>
    <child link="r_gripper"/>
    <origin rpy="0 0 0" xyz="0.058 0 -0.0159"/>
    <limit effort="0.177576" lower="0" upper="1.0" velocity="3"/>
  </joint>
  <link name="r_gripper">
    <inertial>
      <mass value="2e-06"/>
      <inertia ixx="1.1e-09" ixy="0" ixz="0" iyy="1.1e-09" iyz="0" izz="1.1e-09"/>
      <origin rpy="0 0 0" xyz="0 0 0"/>
    </inertial>
  </link>
  <link name="RFsrFL_frame"/>
  <joint name="RFsrFL_joint" type="fixed">
    <parent link="r_ankle"/>
    <child link="RFsrFL_frame"/>
    <origin rpy="0 0 0" xyz="0.07025 0.0231 0"/>
  </joint>
  <link name="RFsrRL_frame"/>
  <joint name="RFsrRL_joint" type="fixed">
    <parent link="r_ankle"/>
    <child link="RFsrRL_frame"/>
    <origin rpy="0 0 0" xyz="-0.03025 0.0191 0"/>
  </joint>
  <link name="LSonar_frame"/>
  <joint name="LSonar_joint" type="fixed">
    <parent link="torso"/>
    <child link="LSonar_frame"/>
    <origin rpy="0 0.04365 0.39265" xyz="0.0507 0.03785 0.06035"/>
  </joint>
  <link name="LFsrFR_frame"/>
  <joint name="LFsrFR_joint" type="fixed">
    <parent link="l_ankle"/>
    <child link="LFsrFR_frame"/>
    <origin rpy="0 0 0" xyz="0.07025 -0.0231 0"/>
  </joint>
  <link name="ImuAccelerometer_frame"/>
  <joint name="ImuAccelerometer_joint" type="fixed">
    <parent link="torso"/>
    <child link="ImuAccelerometer_frame"/>
    <origin rpy="0 0 0" xyz="-0.008 0.00606 0.027"/>
  </joint>
  <link name="ImuGyrometer_frame"/>
  <joint name="ImuGyrometer_joint" type="fixed">
    <parent link="torso"/>
    <child link="ImuGyrometer_frame"/>
    <origin rpy="0 0 0" xyz="-0.008 -0.006 0.029"/>
  </joint>
  <link name="LFsrRL_frame"/>
  <joint name="LFsrRL_joint" type="fixed">
    <parent link="l_ankle"/>
    <child link="LFsrRL_frame"/>
    <origin rpy="0 0 0" xyz="-0.03025 0.0299 0"/>
  </joint>
  <link name="RFootBumperRight_frame"/>
  <joint name="RFootBumperRight_joint" type="fixed">
    <parent link="r_ankle"/>
    <child link="RFootBumperRight_frame"/>
    <origin rpy="0 0 0" xyz="0.0876 -0.019 -0.035"/>
  </joint>
  <link name="RInfraRed_frame"/>
  <joint name="RInfraRed_joint" type="fixed">
    <parent link="Head"/>
    <child link="RInfraRed_frame"/>
    <origin rpy="0 0 0" xyz="0.0441 -0.0257 0.0466"/>
  </joint>
  <link name="LFootBumperLeft_frame"/>
  <joint name="LFootBumperLeft_joint" type="fixed">
    <parent link="l_ankle"/>
    <child link="LFootBumperLeft_frame"/>
    <origin rpy="0 0 0" xyz="0.0876 0.019 -0.035"/>
  </joint>
  <link name="ChestButton_frame"/>
  <joint name="ChestButton_joint" type="fixed">
    <parent link="torso"/>
    <child link="ChestButton_frame"/>
    <origin rpy="0 0 0" xyz="0.049871 0.001588 0.055163"/>
  </joint>
  <link name="RFootBumperLeft_frame"/>
  <joint name="RFootBumperLeft_joint" type="fixed">
    <parent link="r_ankle"/>
    <child link="RFootBumperLeft_frame"/>
    <origin rpy="0 0 0" xyz="0.0876 0.014 -0.035"/>
  </joint>
  <link name="LFsrRR_frame"/>
  <joint name="LFsrRR_joint" type="fixed">
    <parent link="l_ankle"/>
    <child link="LFsrRR_frame"/>
    <origin rpy="0 0 0" xyz="-0.02965 -0.0191 0"/>
  </joint>
  <link name="LFootBumperRight_frame"/>
  <joint name="LFootBumperRight_joint" type="fixed">
    <parent link="l_ankle"/>
    <child link="LFootBumperRight_frame"/>
    <origin rpy="0 0 0" xyz="0.0876 -0.014 -0.035"/>
  </joint>
  <link name="RFsrFR_frame"/>
  <joint name="RFsrFR_joint" type="fixed">
    <parent link="r_ankle"/>
    <child link="RFsrFR_frame"/>
    <origin rpy="0 0 0" xyz="0.07025 -0.0299 0"/>
  </joint>
  <link name="RFsrRR_frame"/>
  <joint name="RFsrRR_joint" type="fixed">
    <parent link="r_ankle"/>
    <child link="RFsrRR_frame"/>
    <origin rpy="0 0 0" xyz="-0.02965 -0.0299 0"/>
  </joint>
  <link name="LFsrFL_frame"/>
  <joint name="LFsrFL_joint" type="fixed">
    <parent link="l_ankle"/>
    <child link="LFsrFL_frame"/>
    <origin rpy="0 0 0" xyz="0.07025 0.0299 0"/>
  </joint>
  <link name="CameraBottom_frame"/>
  <joint name="CameraBottom_joint" type="fixed">
    <parent link="Head"/>
    <child link="CameraBottom_frame"/>
    <origin rpy="0 0.6981 0" xyz="0.0488 0 0.02381"/>
  </joint>
  <link name="RSonar_frame"/>
  <joint name="RSonar_joint" type="fixed">
    <parent link="torso"/>
    <child link="RSonar_frame"/>
    <origin rpy="0 0.04365 -0.39265" xyz="0.0507 -0.03785 0.06035"/>
  </joint>
  <link name="CameraTop_frame"/>
  <joint name="CameraTop_joint" type="fixed">
    <parent link="Head"/>
    <child link="CameraTop_frame"/>
    <origin rpy="0 0 0" xyz="0.0539 0 0.0679"/>
  </joint>
  <link name="LInfraRed_frame"/>
  <joint name="LInfraRed_joint" type="fixed">
    <parent link="Head"/>
    <child link="LInfraRed_frame"/>
    <origin rpy="0 0 0" xyz="0.0441 0.0257 0.0466"/>
  </joint>
</robot>

