<?xml version="1.0" ?>
<!-- ***************************************************************** 
 ****** File automatically generated by generate_urdf.py script ****** 
 ********************************************************************* -->
<robot xmlns:xacro="http://www.ros.org/wiki/xacro">
	<joint name="HeadYaw" type="revolute">
		<parent link="torso"/>
		<child link="Neck"/>
		<origin rpy="0 0 0" xyz="0 0 0.1265"/>
		<axis xyz="0 0 1.0"/>
		<limit effort="1.2" lower="-2.08567" upper="2.08567" velocity="8.26797"/>
	</joint>
	<link name="Neck">
		<inertial>
			<mass value="0.05959"/>
			<inertia ixx="6.22337e-05" ixy="0" ixz="-7.448e-08" iyy="6.32443e-05" iyz="-1.0416e-07" izz="5.49462e-06"/>
			<origin rpy="0 0 0" xyz="-3e-05 0 -0.02573"/>
		</inertial>
		<xacro:insert_visu_Neck/>
	</link>
	<joint name="HeadPitch" type="revolute">
		<parent link="Neck"/>
		<child link="Head"/>
		<origin rpy="0 0 0" xyz="0 0 0"/>
		<axis xyz="0 1.0 0"/>
		<limit effort="1.2" lower="-0.671952" upper="0.514872" velocity="7.19407"/>
	</joint>
	<link name="Head">
		<inertial>
			<mass value="0.47672"/>
			<inertia ixx="0.00487953" ixy="1.42859e-05" ixz="0.000195457" iyy="0.00470361" iyz="-2.22459e-05" izz="0.00156714"/>
			<origin rpy="0 0 0" xyz="0.00383 0 0.05156"/>
		</inertial>
		<xacro:insert_visu_Head/>
	</link>
	<joint name="gaze_joint" type="fixed">
		<parent link="Head"/>
		<child link="gaze"/>
		<origin rpy="0 0 0" xyz="0.0539 0 0.0679"/>
	</joint>
	<link name="gaze"/>
</robot>
